Workbook

Sheet ISE
A1: Textbox2 | B1: Textbox7 | C1: Textbox1 | D1: Textbox5 | E1: Textbox3 | F1: Textbox8 | G1: Textbox9 | H1: Textbox10 | I1: Textbox11 | J1: Textbox12 | K1: ItemCode | L1: Description | M1: Unit | N1: Day1 | O1: Day2 | P1: Day3 | Q1: Day4 | R1: Day5 | S1: Day6 | T1: Day7
A2: Item Code | B2: Item | C2: Unit | D2: Monday 29-Jun-26 | E2: Tuesday 30-Jun-26 | F2: Wednesday 01-Jul-26 | G2: Thursday 02-Jul-26 | H2: Friday 03-Jul-26 | I2: Saturday 04-Jul-26 | J2: Sunday 05-Jul-26 | K2: 106431 | L2: 260 x 260mm Baking Paper Golden Silidor | M2: CARTON-1000 | N2: 0.03 | O2: 0.02 | P2: 0.03 | Q2: 0.01 | R2: 0.03 | S2: 0.03 | T2: 0.04
A3: Item Code | B3: Item | C3: Unit | D3: Monday 29-Jun-26 | E3: Tuesday 30-Jun-26 | F3: Wednesday 01-Jul-26 | G3: Thursday 02-Jul-26 | H3: Friday 03-Jul-26 | I3: Saturday 04-Jul-26 | J3: Sunday 05-Jul-26 | K3: 106491 | L3: 4OZ PORTION CUP 50EA | M3: PACK-50 | N3: 0.66 | O3: 0.24 | P3: 0.54 | Q3: 0.3 | R3: 0.42 | S3: 0.38 | T3: 0.48
A4: Item Code | B4: Item | C4: Unit | D4: Monday 29-Jun-26 | E4: Tuesday 30-Jun-26 | F4: Wednesday 01-Jul-26 | G4: Thursday 02-Jul-26 | H4: Friday 03-Jul-26 | I4: Saturday 04-Jul-26 | J4: Sunday 05-Jul-26 | K4: 106551 | L4: 4OZ PORTION CUP LID 50EA | M4: PACK-50 | N4: 0.66 | O4: 0.24 | P4: 0.54 | Q4: 0.3 | R4: 0.42 | S4: 0.38 | T4: 0.48
A5: Item Code | B5: Item | C5: Unit | D5: Monday 29-Jun-26 | E5: Tuesday 30-Jun-26 | F5: Wednesday 01-Jul-26 | G5: Thursday 02-Jul-26 | H5: Friday 03-Jul-26 | I5: Saturday 04-Jul-26 | J5: Sunday 05-Jul-26 | K5: 37995 | L5: BAG CHIPS LARGE | M5: CARTON-3000 | N5: 0.03 | O5: 0.03 | P5: 0.04 | Q5: 0.03 | R5: 0.06 | S5: 0.04 | T5: 0.04
A6: Item Code | B6: Item | C6: Unit | D6: Monday 29-Jun-26 | E6: Tuesday 30-Jun-26 | F6: Wednesday 01-Jul-26 | G6: Thursday 02-Jul-26 | H6: Friday 03-Jul-26 | I6: Saturday 04-Jul-26 | J6: Sunday 05-Jul-26 | K6: 37993 | L6: BAG CHIPS REGULAR | M6: CARTON-3000 | N6: 0.04 | O6: 0.05 | P6: 0.06 | Q6: 0.05 | R6: 0.06 | S6: 0.06 | T6: 0.06
A7: Item Code | B7: Item | C7: Unit | D7: Monday 29-Jun-26 | E7: Tuesday 30-Jun-26 | F7: Wednesday 01-Jul-26 | G7: Thursday 02-Jul-26 | H7: Friday 03-Jul-26 | I7: Saturday 04-Jul-26 | J7: Sunday 05-Jul-26 | K7: 37893 | L7: BAG CRUNCHWRAP | M7: CARTON-2000 | N7: 0.05 | O7: 0.04 | P7: 0.05 | Q7: 0.05 | R7: 0.07 | S7: 0.07 | T7: 0.06
A8: Item Code | B8: Item | C8: Unit | D8: Monday 29-Jun-26 | E8: Tuesday 30-Jun-26 | F8: Wednesday 01-Jul-26 | G8: Thursday 02-Jul-26 | H8: Friday 03-Jul-26 | I8: Saturday 04-Jul-26 | J8: Sunday 05-Jul-26 | K8: 37997 | L8: BAG NACHO CHIPS LARGE | M8: CARTON-500 | N8: 0.04 | O8: 0.06 | P8: 0.05 | Q8: 0.04 | R8: 0.07 | S8: 0.05 | T8: 0.08
A9: Item Code | B9: Item | C9: Unit | D9: Monday 29-Jun-26 | E9: Tuesday 30-Jun-26 | F9: Wednesday 01-Jul-26 | G9: Thursday 02-Jul-26 | H9: Friday 03-Jul-26 | I9: Saturday 04-Jul-26 | J9: Sunday 05-Jul-26 | K9: 37991 | L9: BAG TAKEAWAY BROWN LARGE 2 | M9: CARTON-250 | N9: 0.19 | O9: 0.19 | P9: 0.22 | Q9: 0.2 | R9: 0.28 | S9: 0.26 | T9: 0.25
A10: Item Code | B10: Item | C10: Unit | D10: Monday 29-Jun-26 | E10: Tuesday 30-Jun-26 | F10: Wednesday 01-Jul-26 | G10: Thursday 02-Jul-26 | H10: Friday 03-Jul-26 | I10: Saturday 04-Jul-26 | J10: Sunday 05-Jul-26 | K10: 37989 | L10: BAG TAKEAWAY BROWN MEDIUM | M10: CARTON-1000 | N10: 0.21 | O10: 0.21 | P10: 0.24 | Q10: 0.22 | R10: 0.31 | S10: 0.28 | T10: 0.27
A11: Item Code | B11: Item | C11: Unit | D11: Monday 29-Jun-26 | E11: Tuesday 30-Jun-26 | F11: Wednesday 01-Jul-26 | G11: Thursday 02-Jul-26 | H11: Friday 03-Jul-26 | I11: Saturday 04-Jul-26 | J11: Sunday 05-Jul-26 | K11: 37987 | L11: BAG TAKEAWAY BROWN SMALL | M11: CARTON-1000 | N11: 0.05 | O11: 0.05 | P11: 0.06 | Q11: 0.06 | R11: 0.08 | S11: 0.07 | T11: 0.07
A12: Item Code | B12: Item | C12: Unit | D12: Monday 29-Jun-26 | E12: Tuesday 30-Jun-26 | F12: Wednesday 01-Jul-26 | G12: Thursday 02-Jul-26 | H12: Friday 03-Jul-26 | I12: Saturday 04-Jul-26 | J12: Sunday 05-Jul-26 | K12: 37862 | L12: BEANS BLACK COOKED | M12: CARTON-12x1KG | N12: 0.57 | O12: 0.5 | P12: 0.62 | Q12: 0.59 | R12: 0.71 | S12: 0.82 | T12: 0.65
A13: Item Code | B13: Item | C13: Unit | D13: Monday 29-Jun-26 | E13: Tuesday 30-Jun-26 | F13: Wednesday 01-Jul-26 | G13: Thursday 02-Jul-26 | H13: Friday 03-Jul-26 | I13: Saturday 04-Jul-26 | J13: Sunday 05-Jul-26 | K13: 38892 | L13: BIG BELL BOX 2 | M13: CARTON-250 | N13: 0.18 | O13: 0.19 | P13: 0.24 | Q13: 0.2 | R13: 0.27 | S13: 0.2 | T13: 0.24
... A62: Item Code | B62: Item | C62: Unit | D62: Monday 29-Jun-26 | E62: Tuesday 30-Jun-26 | F62: Wednesday 01-Jul-26 | G62: Thursday 02-Jul-26 | H62: Friday 03-Jul-26 | I62: Saturday 04-Jul-26 | J62: Sunday 05-Jul-26 | K62: 20295 | L62: JALAPENO | M62: CARTON-6x2.3KG | N62: 0.01 | O62: 0.01 | P62: 0 | Q62: 0.01 | R62: 0.02 | S62: 0 | T62: 0
A63: Item Code | B63: Item | C63: Unit | D63: Monday 29-Jun-26 | E63: Tuesday 30-Jun-26 | F63: Wednesday 01-Jul-26 | G63: Thursday 02-Jul-26 | H63: Friday 03-Jul-26 | I63: Saturday 04-Jul-26 | J63: Sunday 05-Jul-26 | K63: 39391 | L63: LABELS DELIVERY TB TAMPER PROOF | N63: 0 | O63: 0 | P63: 0 | Q63: 0 | R63: 0 | S63: 0 | T63: 0
A64: Item Code | B64: Item | C64: Unit | D64: Monday 29-Jun-26 | E64: Tuesday 30-Jun-26 | F64: Wednesday 01-Jul-26 | G64: Thursday 02-Jul-26 | H64: Friday 03-Jul-26 | I64: Saturday 04-Jul-26 | J64: Sunday 05-Jul-26 | K64: 38701 | L64: LAVA SAUCE | M64: CARTON-10x1KG | N64: 0.18 | O64: 0.12 | P64: 0.18 | Q64: 0.11 | R64: 0.22 | S64: 0.15 | T64: 0.17
A65: Item Code | B65: Item | C65: Unit | D65: Monday 29-Jun-26 | E65: Tuesday 30-Jun-26 | F65: Wednesday 01-Jul-26 | G65: Thursday 02-Jul-26 | H65: Friday 03-Jul-26 | I65: Saturday 04-Jul-26 | J65: Sunday 05-Jul-26 | K65: 13016 | L65: LETTUCE SHREDDED | M65: CARTON-4X2.5KG | N65: 0.8 | O65: 0.81 | P65: 0.92 | Q65: 0.88 | R65: 1.18 | S65: 1.03 | T65: 1.02
A66: Item Code | B66: Item | C66: Unit | D66: Monday 29-Jun-26 | E66: Tuesday 30-Jun-26 | F66: Wednesday 01-Jul-26 | G66: Thursday 02-Jul-26 | H66: Friday 03-Jul-26 | I66: Saturday 04-Jul-26 | J66: Sunday 05-Jul-26 | K66: 39746 | L66: LID CLEAR 60ML DIPPING CUP | M66: CARTON-1000 | N66: 0.13 | O66: 0.14 | P66: 0.19 | Q66: 0.17 | R66: 0.19 | S66: 0.17 | T66: 0.2
A67: Item Code | B67: Item | C67: Unit | D67: Monday 29-Jun-26 | E67: Tuesday 30-Jun-26 | F67: Wednesday 01-Jul-26 | G67: Thursday 02-Jul-26 | H67: Friday 03-Jul-26 | I67: Saturday 04-Jul-26 | J67: Sunday 05-Jul-26 | K67: 37380 | L67: LID FCB DOME 590 ML CH | M67: CARTON-1000 | N67: 0.01 | O67: 0.01 | P67: 0.01 | Q67: 0.01 | R67: 0.01 | S67: 0.01 | T67: 0.01
A68: Item Code | B68: Item | C68: Unit | D68: Monday 29-Jun-26 | E68: Tuesday 30-Jun-26 | F68: Wednesday 01-Jul-26 | G68: Thursday 02-Jul-26 | H68: Friday 03-Jul-26 | I68: Saturday 04-Jul-26 | J68: Sunday 05-Jul-26 | K68: 13735 | L68: LID POSTMIX | M68: CARTON-1000 | N68: 0.16 | O68: 0.13 | P68: 0.19 | Q68: 0.14 | R68: 0.22 | S68: 0.2 | T68: 0.2
A69: Item Code | B69: Item | C69: Unit | D69: Monday 29-Jun-26 | E69: Tuesday 30-Jun-26 | F69: Wednesday 01-Jul-26 | G69: Thursday 02-Jul-26 | H69: Friday 03-Jul-26 | I69: Saturday 04-Jul-26 | J69: Sunday 05-Jul-26 | K69: 39520 | L69: MEAT BEEF COOKED | M69: CARTON-8x1.85KG | N69: 1.32 | O69: 1.42 | P69: 1.71 | Q69: 1.58 | R69: 1.98 | S69: 1.99 | T69: 1.69
A70: Item Code | B70: Item | C70: Unit | D70: Monday 29-Jun-26 | E70: Tuesday 30-Jun-26 | F70: Wednesday 01-Jul-26 | G70: Thursday 02-Jul-26 | H70: Friday 03-Jul-26 | I70: Saturday 04-Jul-26 | J70: Sunday 05-Jul-26 | K70: 39139 | L70: MEAT CHICKEN COOKED | M70: CARTON-10X600GM | N70: 1.64 | O70: 1.24 | P70: 1.65 | Q70: 1.58 | R70: 2.5 | S70: 1.74 | T70: 1.8
A71: Item Code | B71: Item | C71: Unit | D71: Monday 29-Jun-26 | E71: Tuesday 30-Jun-26 | F71: Wednesday 01-Jul-26 | G71: Thursday 02-Jul-26 | H71: Friday 03-Jul-26 | I71: Saturday 04-Jul-26 | J71: Sunday 05-Jul-26 | K71: 36549 | L71: NAPKINS BROWN RECYCLE | M71: CARTON-12x500 | N71: 0.1 | O71: 0.11 | P71: 0.13 | Q71: 0.12 | R71: 0.16 | S71: 0.14 | T71: 0.14
A72: Item Code | B72: Item | C72: Unit | D72: Monday 29-Jun-26 | E72: Tuesday 30-Jun-26 | F72: Wednesday 01-Jul-26 | G72: Thursday 02-Jul-26 | H72: Friday 03-Jul-26 | I72: Saturday 04-Jul-26 | J72: Sunday 05-Jul-26 | K72: 33312 | L72: OIL FRYING LIQUID CARGILL | M72: CARTON-15KG | N72: 0.51 | O72: 0.51 | P72: 0.58 | Q72: 0.54 | R72: 0.74 | S72: 0.66 | T72: 0.64
A73: Item Code | B73: Item | C73: Unit | D73: Monday 29-Jun-26 | E73: Tuesday 30-Jun-26 | F73: Wednesday 01-Jul-26 | G73: Thursday 02-Jul-26 | H73: Friday 03-Jul-26 | I73: Saturday 04-Jul-26 | J73: Sunday 05-Jul-26 | K73: 15659 | L73: ONION BROWN DICED | M73: CARTON-4x1KG | N73: 0.24 | O73: 0.26 | P73: 0.29 | Q73: 0.32 | R73: 0.39 | S73: 0.37 | T73: 0.33
A74: Item Code | B74: Item | C74: Unit | D74: Monday 29-Jun-26 | E74: Tuesday 30-Jun-26 | F74: Wednesday 01-Jul-26 | G74: Thursday 02-Jul-26 | H74: Friday 03-Jul-26 | I74: Saturday 04-Jul-26 | J74: Sunday 05-Jul-26 | K74: 37915 | L74: RICE LONG GRAIN WHITE | M74: BAG-10KG | N74: 0.35 | O74: 0.29 | P74: 0.37 | Q74: 0.26 | R74: 0.47 | S74: 0.44 | T74: 0.39
A75: Item Code | B75: Item | C75: Unit | D75: Monday 29-Jun-26 | E75: Tuesday 30-Jun-26 | F75: Wednesday 01-Jul-26 | G75: Thursday 02-Jul-26 | H75: Friday 03-Jul-26 | I75: Saturday 04-Jul-26 | J75: Sunday 05-Jul-26 | K75: 38670 | L75: SALAD CORIANDER CHOPPED | M75: BAG-500GM | N75: 0.28 | O75: 0.32 | P75: 0.34 | Q75: 0.38 | R75: 0.46 | S75: 0.44 | T75: 0.4
... A103: Item Code | B103: Item | C103: Unit | D103: Monday 29-Jun-26 | E103: Tuesday 30-Jun-26 | F103: Wednesday 01-Jul-26 | G103: Thursday 02-Jul-26 | H103: Friday 03-Jul-26 | I103: Saturday 04-Jul-26 | J103: Sunday 05-Jul-26 | K103: 37999 | L103: WRAP WASTE WHITE UNPRINTED | M103: CARTON-5x1000 | N103: 0.1 | O103: 0.09 | P103: 0.11 | Q103: 0.1 | R103: 0.14 | S103: 0.13 | T103: 0.12

Sheet ISE Average
A1: 3811 Chirnside Park
C2: ######## | D2: ######## | E2: 46209 | F2: ######## | G2: ######## | J2: ######## | K2: ######## | L2: 46210 | M2: ######## | N2: ######## | Q2: ######## | R2: ######## | S2: 46211 | T2: 46204 | U2: ######## | X2: ######## | Y2: ######## | Z2: 46212 | AA2: 46205 | AB2: ######## | AE2: ######## | AF2: ######## | AG2: ######## | AH2: 46206 | AI2: ######## | AL2: ######## | AM2: ######## | AN2: ######## | AO2: 46207 | AP2: ######## | AS2: ######## | AT2: ######## | AU2: 46208 | AV2: ######## | AW2: ########
C3: Monday | D3: Monday | E3: Monday | F3: Monday | G3: Monday | H3: Average of Mondays | J3: Tuesday | K3: Tuesday | L3: Tuesday | M3: Tuesday | N3: Tuesday | O3: Average of Tuesdays | Q3: Wednesday | R3: Wednesday | S3: Wednesday | T3: Wednesday | U3: Wednesday | V3: Average of Wednesdays | X3: Thursday | Y3: Thursday | Z3: Thursday | AA3: Thursday | AB3: Thursday | AC3: Average of Thursdays | AE3: Friday | AF3: Friday | AG3: Friday | AH3: Friday | AI3: Friday | AJ3: Average of Fridays | AL3: Saturday | AM3: Saturday | AN3: Saturday | AO3: Saturday | AP3: Saturday | AQ3: Average of Saturdays | AS3: Sunday | AT3: Sunday | AU3: Sunday | AV3: Sunday | AW3: Sunday | AX3: Average of Sundays
A4: Item | B4: Description
A5: 100399 | B5: DRINK JUICE APPLE SPRING VALLEY | C5: 0 | D5: 0 | E5: 0.06 | F5: 0.06 | G5: 0 | H5: 0.02 | J5: 0.06 | K5: 0.06 | L5: 0 | M5: 0.11 | N5: 0 | O5: 0.04 | Q5: 0.11 | R5: 0.06 | S5: 0 | T5: 0.22 | U5: 0 | V5: 0.0567 | X5: 0 | Y5: 0.11 | Z5: 0 | AA5: 0.06 | AB5: 0.11 | AC5: 0.0567 | AE5: 0 | AF5: 0.06 | AG5: 0 | AH5: 0.11 | AI5: 0.06 | AJ5: 0.04 | AL5: 0.06 | AM5: 0.28 | AN5: 0.11 | AO5: 0.17 | AP5: 0.06 | AQ5: 0.1133 | AS5: 0.06 | AT5: 0.11 | AU5: 0.06 | AV5: 0.11 | AW5: 0 | AX5: 0.0767
A6: 100400 | B6: DRINK JUICE POP TOP APPLE 250ML | C6: 0 | D6: 0.08 | E6: 0.08 | F6: 0.08 | G6: 0.08 | H6: 0.08 | J6: 0.04 | K6: 0.08 | L6: 0.04 | M6: 0 | N6: 0.08 | O6: 0.0533 | Q6: 0.08 | R6: 0 | S6: 0.04 | T6: 0 | U6: 0.08 | V6: 0.04 | X6: 0.08 | Y6: 0 | Z6: 0.08 | AA6: 0.08 | AB6: 0.04 | AC6: 0.0667 | AE6: 0.13 | AF6: 0.13 | AG6: 0.13 | AH6: 0.17 | AI6: 0.04 | AJ6: 0.13 | AL6: 0.13 | AM6: 0.17 | AN6: 0 | AO6: 0.04 | AP6: 0.08 | AQ6: 0.0833 | AS6: 0.08 | AT6: 0.08 | AU6: 0.04 | AV6: 0.04 | AW6: 0 | AX6: 0.0533
A7: 100401 | B7: DRINK JUICE POP TOP ORANGE 250ML | C7: 0 | D7: 0 | E7: 0.13 | F7: 0 | G7: 0 | H7: 0 | J7: 0.04 | K7: 0 | L7: 0.04 | M7: 0 | N7: 0 | O7: 0.0133 | Q7: 0.04 | R7: 0 | S7: 0.04 | T7: 0 | U7: 0.04 | V7: 0.0267 | X7: 0 | Y7: 0 | Z7: 0.04 | AA7: 0.04 | AB7: 0.04 | AC7: 0.0267 | AE7: 0.04 | AF7: 0.13 | AG7: 0.08 | AH7: 0.08 | AI7: 0.04 | AJ7: 0.0667 | AL7: 0 | AM7: 0 | AN7: 0 | AO7: 0 | AP7: 0.04 | AQ7: 0 | AS7: 0 | AT7: 0 | AU7: 0.04 | AV7: 0 | AW7: 0.04 | AX7: 0.0133
A8: 100402 | B8: DRINK WATER SPARKLING 500ML | C8: 0.04 | D8: 0.08 | E8: 0 | G8: 0.04 | H8: 0.0267 | J8: 0 | K8: 0 | L8: 0.04 | N8: 0.04 | O8: 0.0133 | Q8: 0 | R8: 0.08 | S8: 0.08 | U8: 0 | V8: 0.0267 | X8: 0 | Y8: 0.08 | Z8: 0.08 | AB8: 0.04 | AC8: 0.04 | AE8: 0.17 | AF8: 0.13 | AG8: 0 | AI8: 0 | AJ8: 0.0433 | AL8: 0.08 | AM8: 0 | AN8: 0 | AP8: 0 | AQ8: 0 | AS8: 0 | AT8: 0.04 | AU8: 0.04 | AW8: 0.08 | AX8: 0.0267
A9: 100403 | B9: DRINK RED BULL ED 250ML | C9: 0.13 | D9: 0.04 | E9: 0.13 | F9: 0 | G9: 0.08 | H9: 0.0833 | J9: 0.04 | K9: 0.13 | L9: 0.04 | M9: 0.04 | N9: 0 | O9: 0.04 | Q9: 0.21 | R9: 0.04 | S9: 0.08 | T9: 0.04 | U9: 0 | V9: 0.0533 | X9: 0 | Y9: 0.08 | Z9: 0.08 | AA9: 0.08 | AB9: 0.04 | AC9: 0.0667 | AE9: 0.04 | AF9: 0.04 | AG9: 0 | AH9: 0.25 | AI9: 0 | AJ9: 0.0267 | AL9: 0 | AM9: 0 | AN9: 0.04 | AO9: 0.08 | AP9: 0.13 | AQ9: 0.04 | AS9: 0.04 | AT9: 0.08 | AU9: 0.04 | AV9: 0 | AW9: 0.08 | AX9: 0.0533
A10: 100404 | B10: DRINK RED BULL S/FREE 250ML | C10: 0 | D10: 0 | E10: 0.04 | F10: 0 | G10: 0.04 | H10: 0.0133 | J10: 0 | K10: 0 | L10: 0.04 | M10: 0.04 | N10: 0.04 | O10: 0.0267 | Q10: 0.04 | R10: 0 | S10: 0.04 | T10: 0.04 | U10: 0 | V10: 0.0267 | X10: 0 | Y10: 0 | Z10: 0.04 | AA10: 0.04 | AB10: 0.13 | AC10: 0.0267 | AE10: 0 | AF10: 0.04 | AG10: 0 | AH10: 0 | AI10: 0.04 | AJ10: 0.0133 | AL10: 0 | AM10: 0.08 | AN10: 0.04 | AO10: 0.04 | AP10: 0 | AQ10: 0.0267 | AS10: 0.04 | AT10: 0 | AU10: 0 | AV10: 0.08 | AW10: 0 | AX10: 0.0133
A11: 100405 | B11: DRINK RED BULL TROPICAL 250ML | C11: 0.25 | D11: 0 | E11: 0 | F11: 0 | G11: 0.08 | H11: 0.0267 | J11: 0 | K11: 0.33 | L11: 0 | M11: 0.08 | N11: 0.17 | O11: 0.0833 | Q11: 0.08 | R11: 0.08 | S11: 0.08 | T11: 0.08 | U11: 0 | V11: 0.08 | X11: 0 | Y11: 0 | Z11: 0.17 | AA11: 0.17 | AB11: 0 | AC11: 0.0567 | AE11: 0.08 | AF11: 0 | AG11: 0 | AH11: 0 | AI11: 0.08 | AJ11: 0.0267 | AL11: 0.17 | AM11: 0.08 | AN11: 0.08 | AO11: 0.08 | AP11: 0.08 | AQ11: 0.08 | AS11: 0.08 | AT11: 0.08 | AU11: 0.33 | AV11: 0 | AW11: 0.17 | AX11: 0.11
A12: 100457 | B12: SAUCE FIRE 10X1KG | C12: 0.04 | D12: 0.03 | E12: 0.07 | F12: 0.04 | G12: 0.04 | H12: 0.04 | J12: 0.1 | K12: 0.04 | L12: 0.05 | M12: 0.05 | N12: 0.05 | O12: 0.05 | Q12: 0.07 | R12: 0.06 | S12: 0.05 | T12: 0.06 | U12: 0.02 | V12: 0.0567 | X12: 0.05 | Y12: 0.07 | Z12: 0.1 | AA12: 0.09 | AB12: 0.05 | AC12: 0.07 | AE12: 0.08 | AF12: 0.03 | AG12: 0.09 | AH12: 0.1 | AI12: 0.07 | AJ12: 0.08 | AL12: 0.09 | AM12: 0.08 | AN12: 0.05 | AO12: 0.11 | AP12: 0.05 | AQ12: 0.0733 | AS12: 0.03 | AT12: 0.03 | AU12: 0.04 | AV12: 0.04 | AW12: 0.06 | AX12: 0.0367
A13: 106191 | B13: SAUCE CARAMEL MONIN 1.89L | C13: 0.01 | D13: 0.02 | E13: 0.02 | F13: 0.01 | G13: 0.01 | H13: 0.0133 | J13: 0.02 | K13: 0.03 | L13: 0.04 | M13: 0.02 | N13: 0.01 | O13: 0.0233 | Q13: 0.01 | R13: 0.02 | S13: 0.02 | T13: 0.02 | U13: 0 | V13: 0.0167 | X13: 0.03 | Y13: 0.02 | Z13: 0.01 | AA13: 0.04 | AB13: 0.02 | AC13: 0.0233 | AE13: 0.02 | AF13: 0.02 | AG13: 0.01 | AH13: 0.03 | AI13: 0.03 | AJ13: 0.0233 | AL13: 0.01 | AM13: 0.02 | AN13: 0.02 | AO13: 0 | AP13: 0.05 | AQ13: 0.0167 | AS13: 0.04 | AT13: 0 | AU13: 0.01 | AV13: 0.02 | AW13: 0 | AX13: 0.01
A14: 106431 | B14: 260 x 260mm Baking Paper Golden Silidor | C14: 0.02 | D14: 0.02 | E14: 0.02 | F14: 0.01 | G14: 0.01 | H14: 0.0167 | J14: 0.02 | K14: 0.03 | L14: 0.03 | M14: 0.02 | N14: 0.02 | O14: 0.0233 | Q14: 0.03 | R14: 0.03 | S14: 0.01 | T14: 0.02 | U14: 0.02 | V14: 0.0233 | X14: 0.04 | Y14: 0.02 | Z14: 0.03 | AA14: 0.01 | AB14: 0.02 | AC14: 0.0233 | AE14: 0.03 | AF14: 0.02 | AG14: 0.03 | AH14: 0.04 | AI14: 0.02 | AJ14: 0.0267 | AL14: 0.02 | AM14: 0.02 | AN14: 0.04 | AO14: 0.03 | AP14: 0.02 | AQ14: 0.0233 | AS14: 0.02 | AT14: 0.02 | AU14: 0.03 | AV14: 0.01 | AW14: 0.01 | AX14: 0.0167
A15: 106491 | B15: 4OZ PORTION CUP 50EA | C15: 0.5 | D15: 0.34 | E15: 0.24 | F15: 0.14 | G15: 0.22 | H15: 0.2667 | J15: 0.34 | K15: 0.46 | L15: 0.54 | M15: 0.36 | N15: 0.3 | O15: 0.3867 | Q15: 0.48 | R15: 0.64 | S15: 0.3 | T15: 0.38 | U15: 0.42 | V15: 0.4267 | X15: 0.76 | Y15: 0.5 | Z15: 0.42 | AA15: 0.38 | AB15: 0.42 | AC15: 0.4467 | AE15: 0.54 | AF15: 0.62 | AG15: 0.38 | AH15: 0.6 | AI15: 0.48 | AJ15: 0.54 | AL15: 0.5 | AM15: 0.48 | AN15: 0.48 | AO15: 0.52 | AP15: 0.44 | AQ15: 0.4867 | AS15: 0.42 | AT15: 0.42 | AU15: 0.66 | AV15: 0.34 | AW15: 0.32 | AX15: 0.3933
A16: 106551 | B16: 4OZ PORTION CUP LID 50EA | C16: 0.5 | D16: 0.34 | E16: 0.24 | F16: 0.14 | G16: 0.22 | H16: 0.2667 | J16: 0.34 | K16: 0.46 | L16: 0.54 | M16: 0.36 | N16: 0.3 | O16: 0.3867 | Q16: 0.48 | R16: 0.64 | S16: 0.3 | T16: 0.38 | U16: 0.42 | V16: 0.4267 | X16: 0.76 | Y16: 0.5 | Z16: 0.42 | AA16: 0.38 | AB16: 0.42 | AC16: 0.4467 | AE16: 0.54 | AF16: 0.62 | AG16: 0.38 | AH16: 0.6 | AI16: 0.48 | AJ16: 0.54 | AL16: 0.5 | AM16: 0.48 | AN16: 0.48 | AO16: 0.52 | AP16: 0.44 | AQ16: 0.4867 | AS16: 0.42 | AT16: 0.42 | AU16: 0.66 | AV16: 0.34 | AW16: 0.32 | AX16: 0.3933
A17: 11172 | B17: DESSERT CHOCETTES | C17: 0.07 | D17: 0.08 | E17: 0.1 | F17: 0.05 | G17: 0.06 | H17: 0.07 | J17: 0.09 | K17: 0.06 | L17: 0.04 | M17: 0.05 | N17: 0.06 | O17: 0.0567 | Q17: 0.03 | R17: 0.04 | S17: 0.03 | T17: 0.06 | U17: 0.03 | V17: 0.0333 | X17: 0.09 | Y17: 0.1 | Z17: 0.08 | AA17: 0.09 | AB17: 0.06 | AC17: 0.0867 | AE17: 0.12 | AF17: 0.06 | AG17: 0.07 | AH17: 0.06 | AI17: 0.07 | AJ17: 0.0667 | AL17: 0.06 | AM17: 0.07 | AN17: 0.07 | AO17: 0.17 | AP17: 0.13 | AQ17: 0.09 | AS17: 0.07 | AT17: 0.02 | AU17: 0.07 | AV17: 0.02 | AW17: 0.04 | AX17: 0.0433
A18: 12128 | B18: DRINK PEPSI MAX 600ML | C18: 0.13 | D18: 0.13 | E18: 0.21 | F18: 0.21 | G18: 0.17 | H18: 0.17 | J18: 0.38 | K18: 0.33 | L18: 0.54 | M18: 0.29 | N18: 0.21 | O18: 0.3333 | Q18: 0.25 | R18: 0.13 | S18: 0.29 | T18: 0.38 | U18: 0.25 | V18: 0.2633 | X18: 0.46 | Y18: 0.54 | Z18: 0.46 | AA18: 0.42 | AB18: 0.38 | AC18: 0.4467 | AE18: 0.38 | AF18: 0.25 | AG18: 0.42 | AH18: 0.38 | AI18: 0.29 | AJ18: 0.35 | AL18: 0.42 | AM18: 0.58 | AN18: 0.33 | AO18: 0.58 | AP18: 0.29 | AQ18: 0.4433 | AS18: 0.13 | AT18: 0.21 | AU18: 0.46 | AV18: 0.25 | AW18: 0.13 | AX18: 0.1967
A19: 12150 | B19: DRINK PEPSI CAN | C19: 0.1 | D19: 0.07 | E19: 0.07 | F19: 0.03 | G19: 0.07 | H19: 0.07 | J19: 0.1 | K19: 0.07 | L19: 0.1 | M19: 0 | N19: 0.03 | O19: 0.0667 | Q19: 0.13 | R19: 0.13 | S19: 0.13 | T19: 0 | U19: 0.1 | V19: 0.12 | X19: 0.13 | Y19: 0.17 | Z19: 0.07 | AA19: 0.07 | AB19: 0.1 | AC19: 0.1 | AE19: 0.1 | AF19: 0.07 | AG19: 0.07 | AH19: 0.13 | AI19: 0.1 | AJ19: 0.09 | AL19: 0.03 | AM19: 0.03 | AN19: 0.1 | AO19: 0.13 | AP19: 0.03 | AQ19: 0.0533 | AS19: 0.1 | AT19: 0.03 | AU19: 0.13 | AV19: 0.03 | AW19: 0.03 | AX19: 0.0533
A20: 12151 | B20: DRINK PEPSI POST MIX | C20: 0.39 | D20: 0.54 | E20: 0.37 | F20: 0.36 | G20: 0.42 | H20: 0.3933 | J20: 0.46 | K20: 0.46 | L20: 0.69 | M20: 0.4 | N20: 0.51 | O20: 0.4767 | Q20: 0.42 | R20: 0.52 | S20: 0.4 | T20: 0.59 | U20: 0.4 | V20: 0.4467 | X20: 0.84 | Y20: 0.71 | Z20: 0.67 | AA20: 0.5 | AB20: 0.63 | AC20: 0.67 | AE20: 0.72 | AF20: 0.63 | AG20: 0.68 | AH20: 0.58 | AI20: 0.78 | AJ20: 0.6767 | AL20: 0.62 | AM20: 0.54 | AN20: 0.65 | AO20: 0.65 | AP20: 0.62 | AQ20: 0.63 | AS20: 0.5 | AT20: 0.54 | AU20: 0.54 | AV20: 0.33 | AW20: 0.36 | AX20: 0.4667
... A105: 40303 | B105: CHICKEN CRISPY | C105: 0.37 | D105: 0.33 | E105: 0.42 | F105: 0.27 | G105: 0.36 | H105: 0.3533 | J105: 0.41 | K105: 0.41 | L105: 0.37 | M105: 0.46 | N105: 0.3 | O105: 0.3967 | Q105: 0.38 | R105: 0.5 | S105: 0.35 | T105: 0.52 | U105: 0.35 | V105: 0.41 | X105: 0.49 | Y105: 0.44 | Z105: 0.5 | AA105: 0.58 | AB105: 0.44 | AC105: 0.4767 | AE105: 0.44 | AF105: 0.49 | AG105: 0.44 | AH105: 0.43 | AI105: 0.54 | AJ105: 0.4567 | AL105: 0.5 | AM105: 0.45 | AN105: 0.66 | AO105: 0.45 | AP105: 0.39 | AQ105: 0.4667 | AS105: 0.38 | AT105: 0.33 | AU105: 0.39 | AV105: 0.29 | AW105: 0.3 | AX105: 0.3367

Sheet Calculations
B5: =SUM(C35:I36) -> 47933.808 | C5: Macromatix Hour by Hour | K5: Hourly Sales % of Daily Total | T5: Cartons
C6: Monday | D6: Tuesday | E6: Wednesday | F6: Thursday | G6: Friday | H6: Saturday | I6: Sunday | K6: Hour | L6: Mon | M6: Tue | N6: Wed | O6: Thu | P6: Fri | Q6: Sat | R6: Sun | T6: Item | U6: Mon | V6: Tue | W6: Wed | X6: Thu | Y6: Fri | Z6: Sat | AA6: Sun
B7: LUNCH | C7: =SUM(C8:C12) -> 1679.364 | D7: =SUM(D8:D12) -> 1748.87 | E7: =SUM(E8:E12) -> 1901.356 | F7: =SUM(F8:F12) -> 1756.914 | G7: =SUM(G8:G12) -> 1935.928 | H7: =SUM(H8:H12) -> 2458.99 | I7: =SUM(I8:I12) -> 2645.636 | K7: =B7 -> LUNCH | L7: =IFERROR(C7/C$24,0) -> 0.37042337 | M7: =IFERROR(D7/D$24,0) -> 0.37665026 | N7: =IFERROR(E7/E$24,0) -> 0.36077547 | O7: =IFERROR(F7/F$24,0) -> 0.32447164 | P7: =IFERROR(G7/G$24,0) -> 0.27397963 | Q7: =IFERROR(H7/H$24,0) -> 0.34744885 | R7: =IFERROR(I7/I$24,0) -> 0.42023439 | T7: MEAT BEEF COOKED | U7: {=AVERAGE(INDEX('ISE Average'!$C$5:$G$105,MATCH(TRIM($T7),INDEX(TRIM('ISE Average'!$B$5:$B$105),0),0),0))} -> 1.314 | V7: {=AVERAGE(INDEX('ISE Average'!$J$5:$N$105,MATCH(TRIM($T7),INDEX(TRIM('ISE Average'!$B$5:$B$105),0),0),0))} -> 1.428 | W7: {=AVERAGE(INDEX('ISE Average'!$Q$5:$U$105,MATCH(TRIM($T7),INDEX(TRIM('ISE Average'!$B$5:$B$105),0),0),0))} -> 1.46 | X7: {=AVERAGE(INDEX('ISE Average'!$X$5:$AB$105,MATCH(TRIM($T7),INDEX(TRIM('ISE Average'!$B$5:$B$105),0),0),0))} -> 1.904 | Y7: {=AVERAGE(INDEX('ISE Average'!$AE$5:$AI$105,MATCH(TRIM($T7),INDEX(TRIM('ISE Average'!$B$5:$B$105),0),0),0))} -> 1.948 | Z7: {=AVERAGE(INDEX('ISE Average'!$AL$5:$AQ$105,MATCH(TRIM($T7),INDEX(TRIM('ISE Average'!$B$5:$B$105),0),0),0))} -> 1.7116667 | AA7: {=AVERAGE(INDEX('ISE Average'!$AS$5:$AW$105,MATCH(TRIM($T7),INDEX(TRIM('ISE Average'!$B$5:$B$105),0),0),0))} -> 1.21
B8: 0.41666667 | C8: =AVERAGE(Sales!B17:F17) -> 106.952 | D8: =AVERAGE(Sales!H17:L17) -> 127.838 | E8: =AVERAGE(Sales!N17:R17) -> 144.856 | F8: =AVERAGE(Sales!T17:X17) -> 152.886 | G8: =AVERAGE(Sales!Z17:AD17) -> 105.056 | H8: =AVERAGE(Sales!AF17:AJ17) -> 157.872 | I8: =AVERAGE(Sales!AL17:AP17) -> 240.578 | J8: //10-11 | K8: =B8 -> 0.41666667 | L8: =IFERROR(C8/C$24,0) -> 0.023590788 | M8: =IFERROR(D8/D$24,0) -> 0.027532187 | N8: =IFERROR(E8/E$24,0) -> 0.027485906 | O8: =IFERROR(F8/F$24,0) -> 0.028235401 | P8: =IFERROR(G8/G$24,0) -> 0.01486791 | Q8: =IFERROR(H8/H$24,0) -> 0.0223069 | R8: =IFERROR(I8/I$24,0) -> 0.038213552 | T8: MEAT CHICKEN COOKED | U8: {=AVERAGE(INDEX('ISE Average'!$C$5:$G$105,MATCH(TRIM($T8),INDEX(TRIM('ISE Average'!$B$5:$B$105),0),0),0))} -> 1.232 | V8: {=AVERAGE(INDEX('ISE Average'!$J$5:$N$105,MATCH(TRIM($T8),INDEX(TRIM('ISE Average'!$B$5:$B$105),0),0),0))} -> 1.48 | W8: {=AVERAGE(INDEX('ISE Average'!$Q$5:$U$105,MATCH(TRIM($T8),INDEX(TRIM('ISE Average'!$B$5:$B$105),0),0),0))} -> 1.56 | X8: {=AVERAGE(INDEX('ISE Average'!$X$5:$AB$105,MATCH(TRIM($T8),INDEX(TRIM('ISE Average'!$B$5:$B$105),0),0),0))} -> 2.192 | Y8: {=AVERAGE(INDEX('ISE Average'!$AE$5:$AI$105,MATCH(TRIM($T8),INDEX(TRIM('ISE Average'!$B$5:$B$105),0),0),0))} -> 2.152 | Z8: {=AVERAGE(INDEX('ISE Average'!$AL$5:$AQ$105,MATCH(TRIM($T8),INDEX(TRIM('ISE Average'!$B$5:$B$105),0),0),0))} -> 1.9666667 | AA8: {=AVERAGE(INDEX('ISE Average'!$AS$5:$AW$105,MATCH(TRIM($T8),INDEX(TRIM('ISE Average'!$B$5:$B$105),0),0),0))} -> 1.28
B9: 0.45833333 | C9: =AVERAGE(Sales!B18:F18) -> 266.598 | D9: =AVERAGE(Sales!H18:L18) -> 327.322 | E9: =AVERAGE(Sales!N18:R18) -> 355.57 | F9: =AVERAGE(Sales!T18:X18) -> 255.468 | G9: =AVERAGE(Sales!Z18:AD18) -> 288.53 | H9: =AVERAGE(Sales!AF18:AJ18) -> 374.696 | I9: =AVERAGE(Sales!AL18:AP18) -> 379.852 | J9: //11-12 | K9: =B9 -> 0.45833333 | L9: =IFERROR(C9/C$24,0) -> 0.058804482 | M9: =IFERROR(D9/D$24,0) -> 0.070494614 | N9: =IFERROR(E9/E$24,0) -> 0.06746813 | O9: =IFERROR(F9/F$24,0) -> 0.047180523 | P9: =IFERROR(G9/G$24,0) -> 0.040833823 | Q9: =IFERROR(H9/H$24,0) -> 0.052943564 | R9: =IFERROR(I9/I$24,0) -> 0.060335916 | T9: BEANS BLACK COOKED | U9: {=AVERAGE(INDEX('ISE Average'!$C$5:$G$105,MATCH(TRIM($T9),INDEX(TRIM('ISE Average'!$B$5:$B$105),0),0),0))} -> 0.498 | V9: {=AVERAGE(INDEX('ISE Average'!$J$5:$N$105,MATCH(TRIM($T9),INDEX(TRIM('ISE Average'!$B$5:$B$105),0),0),0))} -> 0.576 | W9: {=AVERAGE(INDEX('ISE Average'!$Q$5:$U$105,MATCH(TRIM($T9),INDEX(TRIM('ISE Average'!$B$5:$B$105),0),0),0))} -> 0.532 | X9: {=AVERAGE(INDEX('ISE Average'!$X$5:$AB$105,MATCH(TRIM($T9),INDEX(TRIM('ISE Average'!$B$5:$B$105),0),0),0))} -> 0.804 | Y9: {=AVERAGE(INDEX('ISE Average'!$AE$5:$AI$105,MATCH(TRIM($T9),INDEX(TRIM('ISE Average'!$B$5:$B$105),0),0),0))} -> 0.752 | Z9: {=AVERAGE(INDEX('ISE Average'!$AL$5:$AQ$105,MATCH(TRIM($T9),INDEX(TRIM('ISE Average'!$B$5:$B$105),0),0),0))} -> 0.62111667 | AA9: {=AVERAGE(INDEX('ISE Average'!$AS$5:$AW$105,MATCH(TRIM($T9),INDEX(TRIM('ISE Average'!$B$5:$B$105),0),0),0))} -> 0.538
B10: 0.5 | C10: =AVERAGE(Sales!B19:F19) -> 465.768 | D10: =AVERAGE(Sales!H19:L19) -> 486.81 | E10: =AVERAGE(Sales!N19:R19) -> 603.452 | F10: =AVERAGE(Sales!T19:X19) -> 560.954 | G10: =AVERAGE(Sales!Z19:AD19) -> 653.26 | H10: =AVERAGE(Sales!AF19:AJ19) -> 580.09 | I10: =AVERAGE(Sales!AL19:AP19) -> 682.186 | J10: //12-1 | K10: =B10 -> 0.5 | L10: =IFERROR(C10/C$24,0) -> 0.10273613 | M10: =IFERROR(D10/D$24,0) -> 0.10484319 | N10: =IFERROR(E10/E$24,0) -> 0.11450285 | O10: =IFERROR(F10/F$24,0) -> 0.10359851 | P10: =IFERROR(G10/G$24,0) -> 0.09245175 | Q10: =IFERROR(H10/H$24,0) -> 0.081965198 | R10: =IFERROR(I10/I$24,0) -> 0.10835883 | T10: SAUCE NACHO CHEESE | U10: {=AVERAGE(INDEX('ISE Average'!$C$5:$G$105,MATCH(TRIM($T10),INDEX(TRIM('ISE Average'!$B$5:$B$105),0),0),0))} -> 0.818 | V10: {=AVERAGE(INDEX('ISE Average'!$J$5:$N$105,MATCH(TRIM($T10),INDEX(TRIM('ISE Average'!$B$5:$B$105),0),0),0))} -> 0.948 | W10: {=AVERAGE(INDEX('ISE Average'!$Q$5:$U$105,MATCH(TRIM($T10),INDEX(TRIM('ISE Average'!$B$5:$B$105),0),0),0))} -> 0.95 | X10: {=AVERAGE(INDEX('ISE Average'!$X$5:$AB$105,MATCH(TRIM($T10),INDEX(TRIM('ISE Average'!$B$5:$B$105),0),0),0))} -> 1.25 | Y10: {=AVERAGE(INDEX('ISE Average'!$AE$5:$AI$105,MATCH(TRIM($T10),INDEX(TRIM('ISE Average'!$B$5:$B$105),0),0),0))} -> 1.186 | Z10: {=AVERAGE(INDEX('ISE Average'!$AL$5:$AQ$105,MATCH(TRIM($T10),INDEX(TRIM('ISE Average'!$B$5:$B$105),0),0),0))} -> 1.1411167 | AA10: {=AVERAGE(INDEX('ISE Average'!$AS$5:$AW$105,MATCH(TRIM($T10),INDEX(TRIM('ISE Average'!$B$5:$B$105),0),0),0))} -> 0.782
B11: 0.54166667 | C11: =AVERAGE(Sales!B20:F20) -> 500.514 | D11: =AVERAGE(Sales!H20:L20) -> 474.03 | E11: =AVERAGE(Sales!N20:R20) -> 474.086 | F11: =AVERAGE(Sales!T20:X20) -> 526.818 | G11: =AVERAGE(Sales!Z20:AD20) -> 501.21 | H11: =AVERAGE(Sales!AF20:AJ20) -> 689.032 | I11: =AVERAGE(Sales!AL20:AP20) -> 768.818 | J11: //1-2 | K11: =B11 -> 0.54166667 | L11: =IFERROR(C11/C$24,0) -> 0.11040018 | M11: =IFERROR(D11/D$24,0) -> 0.10209079 | N11: =IFERROR(E11/E$24,0) -> 0.089956115 | O11: =IFERROR(F11/F$24,0) -> 0.097294177 | P11: =IFERROR(G11/G$24,0) -> 0.070933077 | Q11: =IFERROR(H11/H$24,0) -> 0.097358417 | R11: =IFERROR(I11/I$24,0) -> 0.12211951 | T11: TB MEXICAN RICE (FINISHED PRODUCT) | U11: {=AVERAGE(INDEX('ISE Average'!$C$5:$G$105,MATCH(TRIM($T11),INDEX(TRIM('ISE Average'!$B$5:$B$105),0),0),0))} -> 5841.1 | V11: {=AVERAGE(INDEX('ISE Average'!$J$5:$N$105,MATCH(TRIM($T11),INDEX(TRIM('ISE Average'!$B$5:$B$105),0),0),0))} -> 6235.9 | W11: {=AVERAGE(INDEX('ISE Average'!$Q$5:$U$105,MATCH(TRIM($T11),INDEX(TRIM('ISE Average'!$B$5:$B$105),0),0),0))} -> 6118.5 | X11: {=AVERAGE(INDEX('ISE Average'!$X$5:$AB$105,MATCH(TRIM($T11),INDEX(TRIM('ISE Average'!$B$5:$B$105),0),0),0))} -> 8464.6 | Y11: {=AVERAGE(INDEX('ISE Average'!$AE$5:$AI$105,MATCH(TRIM($T11),INDEX(TRIM('ISE Average'!$B$5:$B$105),0),0),0))} -> 9060.8 | Z11: {=AVERAGE(INDEX('ISE Average'!$AL$5:$AQ$105,MATCH(TRIM($T11),INDEX(TRIM('ISE Average'!$B$5:$B$105),0),0),0))} -> 6617.7778 | AA11: {=AVERAGE(INDEX('ISE Average'!$AS$5:$AW$105,MATCH(TRIM($T11),INDEX(TRIM('ISE Average'!$B$5:$B$105),0),0),0))} -> 5631.9
B12: 0.58333333 | C12: =AVERAGE(Sales!B21:F21) -> 339.532 | D12: =AVERAGE(Sales!H21:L21) -> 332.87 | E12: =AVERAGE(Sales!N21:R21) -> 323.392 | F12: =AVERAGE(Sales!T21:X21) -> 260.788 | G12: =AVERAGE(Sales!Z21:AD21) -> 387.872 | H12: =AVERAGE(Sales!AF21:AJ21) -> 657.3 | I12: =AVERAGE(Sales!AL21:AP21) -> 574.202 | J12: //2-3 | K12: =B12 -> 0.58333333 | L12: =IFERROR(C12/C$24,0) -> 0.074891798 | M12: =IFERROR(D12/D$24,0) -> 0.071689474 | N12: =IFERROR(E12/E$24,0) -> 0.06136247 | O12: =IFERROR(F12/F$24,0) -> 0.048163035 | P12: =IFERROR(G12/G$24,0) -> 0.054893068 | Q12: =IFERROR(H12/H$24,0) -> 0.092874769 | R12: =IFERROR(I12/I$24,0) -> 0.091206585 | U12: {=IF($T12="","",_xlfn.XLOOKUP(TRIM($T12),ISE!$L:$L,INDEX(ISE!$N:$T,0,COLUMN()-COLUMN($U$1)+1),""))} | V12: {=IF($T12="","",_xlfn.XLOOKUP(TRIM($T12),ISE!$L:$L,INDEX(ISE!$N:$T,0,COLUMN()-COLUMN($U$1)+1),""))} | W12: {=IF($T12="","",_xlfn.XLOOKUP(TRIM($T12),ISE!$L:$L,INDEX(ISE!$N:$T,0,COLUMN()-COLUMN($U$1)+1),""))} | X12: {=IF($T12="","",_xlfn.XLOOKUP(TRIM($T12),ISE!$L:$L,INDEX(ISE!$N:$T,0,COLUMN()-COLUMN($U$1)+1),""))} | Y12: {=IF($T12="","",_xlfn.XLOOKUP(TRIM($T12),ISE!$L:$L,INDEX(ISE!$N:$T,0,COLUMN()-COLUMN($U$1)+1),""))} | Z12: {=IF($T12="","",_xlfn.XLOOKUP(TRIM($T12),ISE!$L:$L,INDEX(ISE!$N:$T,0,COLUMN()-COLUMN($U$1)+1),""))} | AA12: {=IF($T12="","",_xlfn.XLOOKUP(TRIM($T12),ISE!$L:$L,INDEX(ISE!$N:$T,0,COLUMN()-COLUMN($U$1)+1),""))}
B13: DINNER | C13: =SUM(C14:C20) -> 2854.27 | D13: =SUM(D14:D20) -> 2894.35 | E13: =SUM(E14:E20) -> 3368.836 | F13: =SUM(F14:F20) -> 3657.778 | G13: =SUM(G14:G20) -> 5130.028 | H13: =SUM(H14:H20) -> 4618.282 | I13: =SUM(I14:I20) -> 3649.984 | K13: =B13 -> DINNER | L13: =IFERROR(C13/C$24,0) -> 0.62957663 | M13: =IFERROR(D13/D$24,0) -> 0.62334974 | N13: =IFERROR(E13/E$24,0) -> 0.63922453 | O13: =IFERROR(F13/F$24,0) -> 0.67552836 | P13: =IFERROR(G13/G$24,0) -> 0.72602037 | Q13: =IFERROR(H13/H$24,0) -> 0.65255115 | R13: =IFERROR(I13/I$24,0) -> 0.57976561 | U13: {=IF($T13="","",_xlfn.XLOOKUP(TRIM($T13),ISE!$L:$L,INDEX(ISE!$N:$T,0,COLUMN()-COLUMN($U$1)+1),""))} | V13: {=IF($T13="","",_xlfn.XLOOKUP(TRIM($T13),ISE!$L:$L,INDEX(ISE!$N:$T,0,COLUMN()-COLUMN($U$1)+1),""))} | W13: {=IF($T13="","",_xlfn.XLOOKUP(TRIM($T13),ISE!$L:$L,INDEX(ISE!$N:$T,0,COLUMN()-COLUMN($U$1)+1),""))} | X13: {=IF($T13="","",_xlfn.XLOOKUP(TRIM($T13),ISE!$L:$L,INDEX(ISE!$N:$T,0,COLUMN()-COLUMN($U$1)+1),""))} | Y13: {=IF($T13="","",_xlfn.XLOOKUP(TRIM($T13),ISE!$L:$L,INDEX(ISE!$N:$T,0,COLUMN()-COLUMN($U$1)+1),""))} | Z13: {=IF($T13="","",_xlfn.XLOOKUP(TRIM($T13),ISE!$L:$L,INDEX(ISE!$N:$T,0,COLUMN()-COLUMN($U$1)+1),""))} | AA13: {=IF($T13="","",_xlfn.XLOOKUP(TRIM($T13),ISE!$L:$L,INDEX(ISE!$N:$T,0,COLUMN()-COLUMN($U$1)+1),""))}
B14: 0.625 | C14: =AVERAGE(Sales!B22:F22) -> 292.466 | D14: =AVERAGE(Sales!H22:L22) -> 238.394 | E14: =AVERAGE(Sales!N22:R22) -> 290.972 | F14: =AVERAGE(Sales!T22:X22) -> 327.008 | G14: =AVERAGE(Sales!Z22:AD22) -> 325.37 | H14: =AVERAGE(Sales!AF22:AJ22) -> 512.026 | I14: =AVERAGE(Sales!AL22:AP22) -> 442.856 | J14: //3-4 | K14: =B14 -> 0.625 | L14: =IFERROR(C14/C$24,0) -> 0.06451028 | M14: =IFERROR(D14/D$24,0) -> 0.051342387 | N14: =IFERROR(E14/E$24,0) -> 0.055210892 | O14: =IFERROR(F14/F$24,0) -> 0.060392724 | P14: =IFERROR(G14/G$24,0) -> 0.046047555 | Q14: =IFERROR(H14/H$24,0) -> 0.072347933 | R14: =IFERROR(I14/I$24,0) -> 0.070343509 | U14: {=IF($T14="","",_xlfn.XLOOKUP(TRIM($T14),ISE!$L:$L,INDEX(ISE!$N:$T,0,COLUMN()-COLUMN($U$1)+1),""))} | V14: {=IF($T14="","",_xlfn.XLOOKUP(TRIM($T14),ISE!$L:$L,INDEX(ISE!$N:$T,0,COLUMN()-COLUMN($U$1)+1),""))} | W14: {=IF($T14="","",_xlfn.XLOOKUP(TRIM($T14),ISE!$L:$L,INDEX(ISE!$N:$T,0,COLUMN()-COLUMN($U$1)+1),""))} | X14: {=IF($T14="","",_xlfn.XLOOKUP(TRIM($T14),ISE!$L:$L,INDEX(ISE!$N:$T,0,COLUMN()-COLUMN($U$1)+1),""))} | Y14: {=IF($T14="","",_xlfn.XLOOKUP(TRIM($T14),ISE!$L:$L,INDEX(ISE!$N:$T,0,COLUMN()-COLUMN($U$1)+1),""))} | Z14: {=IF($T14="","",_xlfn.XLOOKUP(TRIM($T14),ISE!$L:$L,INDEX(ISE!$N:$T,0,COLUMN()-COLUMN($U$1)+1),""))} | AA14: {=IF($T14="","",_xlfn.XLOOKUP(TRIM($T14),ISE!$L:$L,INDEX(ISE!$N:$T,0,COLUMN()-COLUMN($U$1)+1),""))}
B15: 0.66666667 | C15: =AVERAGE(Sales!B23:F23) -> 284.476 | D15: =AVERAGE(Sales!H23:L23) -> 314.844 | E15: =AVERAGE(Sales!N23:R23) -> 366.854 | F15: =AVERAGE(Sales!T23:X23) -> 339.788 | G15: =AVERAGE(Sales!Z23:AD23) -> 307.286 | H15: =AVERAGE(Sales!AF23:AJ23) -> 414.248 | I15: =AVERAGE(Sales!AL23:AP23) -> 503.638 | J15: //4-5 | K15: =B15 -> 0.66666667 | L15: =IFERROR(C15/C$24,0) -> 0.062747897 | M15: =IFERROR(D15/D$24,0) -> 0.067807254 | N15: =IFERROR(E15/E$24,0) -> 0.069609229 | O15: =IFERROR(F15/F$24,0) -> 0.062752969 | P15: =IFERROR(G15/G$24,0) -> 0.043488241 | Q15: =IFERROR(H15/H$24,0) -> 0.058532158 | R15: =IFERROR(I15/I$24,0) -> 0.079998157 | T15: Inners
B16: 0.70833333 | C16: =AVERAGE(Sales!B24:F24) -> 459.788 | D16: =AVERAGE(Sales!H24:L24) -> 489.498 | E16: =AVERAGE(Sales!N24:R24) -> 559.686 | F16: =AVERAGE(Sales!T24:X24) -> 623.232 | G16: =AVERAGE(Sales!Z24:AD24) -> 934.354 | H16: =AVERAGE(Sales!AF24:AJ24) -> 929.874 | I16: =AVERAGE(Sales!AL24:AP24) -> 712.568 | J16: //5-6 | K16: =B16 -> 0.70833333 | L16: =IFERROR(C16/C$24,0) -> 0.1014171 | M16: =IFERROR(D16/D$24,0) -> 0.1054221 | N16: =IFERROR(E16/E$24,0) -> 0.10619841 | O16: =IFERROR(F16/F$24,0) -> 0.11510018 | P16: =IFERROR(G16/G$24,0) -> 0.1322332 | Q16: =IFERROR(H16/H$24,0) -> 0.13138876 | R16: =IFERROR(I16/I$24,0) -> 0.11318472 | T16: Item | U16: Mon | V16: Tue | W16: Wed | X16: Thu | Y16: Fri | Z16: Sat | AA16: Sun
B17: 0.75 | C17: =AVERAGE(Sales!B25:F25) -> 750.376 | D17: =AVERAGE(Sales!H25:L25) -> 632.746 | E17: =AVERAGE(Sales!N25:R25) -> 851.578 | F17: =AVERAGE(Sales!T25:X25) -> 889.662 | G17: =AVERAGE(Sales!Z25:AD25) -> 1446.636 | H17: =AVERAGE(Sales!AF25:AJ25) -> 1044.176 | I17: =AVERAGE(Sales!AL25:AP25) -> 853.622 | J17: //6-7 | K17: =B17 -> 0.75 | L17: =IFERROR(C17/C$24,0) -> 0.16551314 | M17: =IFERROR(D17/D$24,0) -> 0.1362731 | N17: =IFERROR(E17/E$24,0) -> 0.16158387 | O17: =IFERROR(F17/F$24,0) -> 0.16430519 | P17: =IFERROR(G17/G$24,0) -> 0.20473323 | Q17: =IFERROR(H17/H$24,0) -> 0.14753933 | R17: =IFERROR(I17/I$24,0) -> 0.13558982 | T17: MEAT BEEF COOKED | U17: =U7*8 -> 10.512 | V17: =V7*8 -> 11.424 | W17: =W7*8 -> 11.68 | X17: =X7*8 -> 15.232 | Y17: =Y7*8 -> 15.584 | Z17: =Z7*8 -> 13.693333 | AA17: =AA7*8 -> 9.68
B18: 0.79166667 | C18: =AVERAGE(Sales!B26:F26) -> 553.476 | D18: =AVERAGE(Sales!H26:L26) -> 499.608 | E18: =AVERAGE(Sales!N26:R26) -> 669.778 | F18: =AVERAGE(Sales!T26:X26) -> 685.382 | G18: =AVERAGE(Sales!Z26:AD26) -> 1172.28 | H18: =AVERAGE(Sales!AF26:AJ26) -> 924.06 | I18: =AVERAGE(Sales!AL26:AP26) -> 627.406 | J18: //7-8 | K18: =B18 -> 0.79166667 | L18: =IFERROR(C18/C$24,0) -> 0.1220822 | M18: =IFERROR(D18/D$24,0) -> 0.10759947 | N18: =IFERROR(E18/E$24,0) -> 0.12708797 | O18: =IFERROR(F18/F$24,0) -> 0.12657821 | P18: =IFERROR(G18/G$24,0) -> 0.16590536 | Q18: =IFERROR(H18/H$24,0) -> 0.13056726 | R18: =IFERROR(I18/I$24,0) -> 0.09965754 | T18: MEAT CHICKEN COOKED | U18: =U8*12 -> 14.784 | V18: =V8*10 -> 14.8 | W18: =W8*10 -> 15.6 | X18: =X8*10 -> 21.92 | Y18: =Y8*10 -> 21.52 | Z18: =Z8*10 -> 19.666667 | AA18: =AA8*10 -> 12.8
B19: 0.83333333 | C19: =AVERAGE(Sales!B27:F27) -> 330.166 | D19: =AVERAGE(Sales!H27:L27) -> 432.582 | E19: =AVERAGE(Sales!N27:R27) -> 408.894 | F19: =AVERAGE(Sales!T27:X27) -> 453.13 | G19: =AVERAGE(Sales!Z27:AD27) -> 624.606 | H19: =AVERAGE(Sales!AF27:AJ27) -> 552.328 | I19: =AVERAGE(Sales!AL27:AP27) -> 392.03 | J19: //8-9 | K19: =B19 -> 0.83333333 | L19: =IFERROR(C19/C$24,0) -> 0.072825905 | M19: =IFERROR(D19/D$24,0) -> 0.093164227 | N19: =IFERROR(E19/E$24,0) -> 0.077586168 | O19: =IFERROR(F19/F$24,0) -> 0.083685277 | P19: =IFERROR(G19/G$24,0) -> 0.088396531 | Q19: =IFERROR(H19/H$24,0) -> 0.0780425 | R19: =IFERROR(I19/I$24,0) -> 0.062270277 | T19: BEANS BLACK COOKED | U19: =U9*10 -> 4.98 | V19: =V9*12 -> 6.912 | W19: =W9*12 -> 6.384 | X19: =X9*12 -> 9.648 | Y19: =Y9*12 -> 9.024 | Z19: =Z9*12 -> 7.4534 | AA19: =AA9*12 -> 6.456
B20: 0.875 | C20: =AVERAGE(Sales!B28:F28) -> 183.522 | D20: =AVERAGE(Sales!H28:L28) -> 286.678 | E20: =AVERAGE(Sales!N28:R28) -> 221.074 | F20: =AVERAGE(Sales!T28:X28) -> 339.576 | G20: =AVERAGE(Sales!Z28:AD28) -> 319.496 | H20: =AVERAGE(Sales!AF28:AJ28) -> 241.57 | I20: =AVERAGE(Sales!AL28:AP28) -> 117.864 | J20: //9-10 | K20: =B20 -> 0.875 | L20: =IFERROR(C20/C$24,0) -> 0.040480109 | M20: =IFERROR(D20/D$24,0) -> 0.061741205 | N20: =IFERROR(E20/E$24,0) -> 0.041947997 | O20: =IFERROR(F20/F$24,0) -> 0.062713816 | P20: =IFERROR(G20/G$24,0) -> 0.045216245 | Q20: =IFERROR(H20/H$24,0) -> 0.034133208 | R20: =IFERROR(I20/I$24,0) -> 0.018721587 | T20: SAUCE NACHO CHEESE | U20: =U10*6 -> 4.908 | V20: =V10*6 -> 5.688 | W20: =W10*6 -> 5.7 | X20: =X10*6 -> 7.5 | Y20: =Y10*6 -> 7.116 | Z20: =Z10*6 -> 6.8467 | AA20: =AA10*6 -> 4.692
B21: 0.91666667 | C21: 0 | D21: 0 | E21: 0 | F21: 0 | G21: 0 | H21: 0 | I21: 0 | K21: =B21 -> 0.91666667 | L21: =IFERROR(C21/C$24,0) -> 0 | M21: =IFERROR(D21/D$24,0) -> 0 | N21: =IFERROR(E21/E$24,0) -> 0 | O21: =IFERROR(F21/F$24,0) -> 0 | P21: =IFERROR(G21/G$24,0) -> 0 | Q21: =IFERROR(H21/H$24,0) -> 0 | R21: =IFERROR(I21/I$24,0) -> 0 | T21: TB MEXICAN RICE (FINISHED PRODUCT) | U21: =U11 -> 5841.1 | V21: =V11 -> 6235.9 | W21: =W11 -> 6118.5 | X21: =X11 -> 8464.6 | Y21: =Y11 -> 9060.8 | Z21: =Z11 -> 6617.7778 | AA21: =AA11 -> 5631.9
B22: 0.95833333 | C22: 0 | D22: 0 | E22: 0 | F22: 0 | G22: 0 | H22: 0 | I22: 0 | K22: =B22 -> 0.95833333 | L22: =IFERROR(C22/C$24,0) -> 0 | M22: =IFERROR(D22/D$24,0) -> 0 | N22: =IFERROR(E22/E$24,0) -> 0 | O22: =IFERROR(F22/F$24,0) -> 0 | P22: =IFERROR(G22/G$24,0) -> 0 | Q22: =IFERROR(H22/H$24,0) -> 0 | R22: =IFERROR(I22/I$24,0) -> 0 | U22: {=IF($T22="","",_xlfn.XLOOKUP(TRIM($T22),ISE!$L:$L,INDEX(ISE!$N:$T,0,COLUMN()-COLUMN($U$1)+1),""))} | V22: {=IF($T22="","",_xlfn.XLOOKUP(TRIM($T22),ISE!$L:$L,INDEX(ISE!$N:$T,0,COLUMN()-COLUMN($U$1)+1),""))} | W22: {=IF($T22="","",_xlfn.XLOOKUP(TRIM($T22),ISE!$L:$L,INDEX(ISE!$N:$T,0,COLUMN()-COLUMN($U$1)+1),""))} | X22: {=IF($T22="","",_xlfn.XLOOKUP(TRIM($T22),ISE!$L:$L,INDEX(ISE!$N:$T,0,COLUMN()-COLUMN($U$1)+1),""))} | Y22: {=IF($T22="","",_xlfn.XLOOKUP(TRIM($T22),ISE!$L:$L,INDEX(ISE!$N:$T,0,COLUMN()-COLUMN($U$1)+1),""))} | Z22: {=IF($T22="","",_xlfn.XLOOKUP(TRIM($T22),ISE!$L:$L,INDEX(ISE!$N:$T,0,COLUMN()-COLUMN($U$1)+1),""))} | AA22: {=IF($T22="","",_xlfn.XLOOKUP(TRIM($T22),ISE!$L:$L,INDEX(ISE!$N:$T,0,COLUMN()-COLUMN($U$1)+1),""))}
K23: =B23 -> 0 | L23: =IFERROR(C23/C$24,0) -> 0 | M23: =IFERROR(D23/D$24,0) -> 0 | N23: =IFERROR(E23/E$24,0) -> 0 | O23: =IFERROR(F23/F$24,0) -> 0 | P23: =IFERROR(G23/G$24,0) -> 0 | Q23: =IFERROR(H23/H$24,0) -> 0 | R23: =IFERROR(I23/I$24,0) -> 0 | U23: {=IF($T23="","",_xlfn.XLOOKUP(TRIM($T23),ISE!$L:$L,INDEX(ISE!$N:$T,0,COLUMN()-COLUMN($U$1)+1),""))} | V23: {=IF($T23="","",_xlfn.XLOOKUP(TRIM($T23),ISE!$L:$L,INDEX(ISE!$N:$T,0,COLUMN()-COLUMN($U$1)+1),""))} | W23: {=IF($T23="","",_xlfn.XLOOKUP(TRIM($T23),ISE!$L:$L,INDEX(ISE!$N:$T,0,COLUMN()-COLUMN($U$1)+1),""))} | X23: {=IF($T23="","",_xlfn.XLOOKUP(TRIM($T23),ISE!$L:$L,INDEX(ISE!$N:$T,0,COLUMN()-COLUMN($U$1)+1),""))} | Y23: {=IF($T23="","",_xlfn.XLOOKUP(TRIM($T23),ISE!$L:$L,INDEX(ISE!$N:$T,0,COLUMN()-COLUMN($U$1)+1),""))} | Z23: {=IF($T23="","",_xlfn.XLOOKUP(TRIM($T23),ISE!$L:$L,INDEX(ISE!$N:$T,0,COLUMN()-COLUMN($U$1)+1),""))} | AA23: {=IF($T23="","",_xlfn.XLOOKUP(TRIM($T23),ISE!$L:$L,INDEX(ISE!$N:$T,0,COLUMN()-COLUMN($U$1)+1),""))}
B24: Totals | C24: =SUM(C8:C12,C14:C22) -> 4533.634 | D24: =SUM(D8:D12,D14:D22) -> 4643.22 | E24: =SUM(E8:E12,E14:E22) -> 5270.192 | F24: =SUM(F8:F12,F14:F22) -> 5414.692 | G24: =SUM(G8:G12,G14:G22) -> 7065.956 | H24: =SUM(H8:H12,H14:H22) -> 7077.272 | I24: =SUM(I8:I12,I14:I22) -> 6295.62 | K24: =B24 -> Totals | L24: =IFERROR(C24/C$24,0) -> 1 | M24: =IFERROR(D24/D$24,0) -> 1 | N24: =IFERROR(E24/E$24,0) -> 1 | O24: =IFERROR(F24/F$24,0) -> 1 | P24: =IFERROR(G24/G$24,0) -> 1 | Q24: =IFERROR(H24/H$24,0) -> 1 | R24: =IFERROR(I24/I$24,0) -> 1 | U24: {=IF($T24="","",_xlfn.XLOOKUP(TRIM($T24),ISE!$L:$L,INDEX(ISE!$N:$T,0,COLUMN()-COLUMN($U$1)+1),""))} | V24: {=IF($T24="","",_xlfn.XLOOKUP(TRIM($T24),ISE!$L:$L,INDEX(ISE!$N:$T,0,COLUMN()-COLUMN($U$1)+1),""))} | W24: {=IF($T24="","",_xlfn.XLOOKUP(TRIM($T24),ISE!$L:$L,INDEX(ISE!$N:$T,0,COLUMN()-COLUMN($U$1)+1),""))} | X24: {=IF($T24="","",_xlfn.XLOOKUP(TRIM($T24),ISE!$L:$L,INDEX(ISE!$N:$T,0,COLUMN()-COLUMN($U$1)+1),""))} | Y24: {=IF($T24="","",_xlfn.XLOOKUP(TRIM($T24),ISE!$L:$L,INDEX(ISE!$N:$T,0,COLUMN()-COLUMN($U$1)+1),""))} | Z24: {=IF($T24="","",_xlfn.XLOOKUP(TRIM($T24),ISE!$L:$L,INDEX(ISE!$N:$T,0,COLUMN()-COLUMN($U$1)+1),""))} | AA24: {=IF($T24="","",_xlfn.XLOOKUP(TRIM($T24),ISE!$L:$L,INDEX(ISE!$N:$T,0,COLUMN()-COLUMN($U$1)+1),""))}
J25: //Day Totals | U25: {=IF($T25="","",_xlfn.XLOOKUP(TRIM($T25),ISE!$L:$L,INDEX(ISE!$N:$T,0,COLUMN()-COLUMN($U$1)+1),""))} | V25: {=IF($T25="","",_xlfn.XLOOKUP(TRIM($T25),ISE!$L:$L,INDEX(ISE!$N:$T,0,COLUMN()-COLUMN($U$1)+1),""))} | W25: {=IF($T25="","",_xlfn.XLOOKUP(TRIM($T25),ISE!$L:$L,INDEX(ISE!$N:$T,0,COLUMN()-COLUMN($U$1)+1),""))} | X25: {=IF($T25="","",_xlfn.XLOOKUP(TRIM($T25),ISE!$L:$L,INDEX(ISE!$N:$T,0,COLUMN()-COLUMN($U$1)+1),""))} | Y25: {=IF($T25="","",_xlfn.XLOOKUP(TRIM($T25),ISE!$L:$L,INDEX(ISE!$N:$T,0,COLUMN()-COLUMN($U$1)+1),""))} | Z25: {=IF($T25="","",_xlfn.XLOOKUP(TRIM($T25),ISE!$L:$L,INDEX(ISE!$N:$T,0,COLUMN()-COLUMN($U$1)+1),""))} | AA25: {=IF($T25="","",_xlfn.XLOOKUP(TRIM($T25),ISE!$L:$L,INDEX(ISE!$N:$T,0,COLUMN()-COLUMN($U$1)+1),""))}
B26: =SUM(C36:I37) -> 0 | C26: Cook time blocks | K26: Cook Time Blocks % of Daily Total | U26: {=IF($T26="","",_xlfn.XLOOKUP(TRIM($T26),ISE!$L:$L,INDEX(ISE!$N:$T,0,COLUMN()-COLUMN($U$1)+1),""))} | V26: {=IF($T26="","",_xlfn.XLOOKUP(TRIM($T26),ISE!$L:$L,INDEX(ISE!$N:$T,0,COLUMN()-COLUMN($U$1)+1),""))} | W26: {=IF($T26="","",_xlfn.XLOOKUP(TRIM($T26),ISE!$L:$L,INDEX(ISE!$N:$T,0,COLUMN()-COLUMN($U$1)+1),""))} | X26: {=IF($T26="","",_xlfn.XLOOKUP(TRIM($T26),ISE!$L:$L,INDEX(ISE!$N:$T,0,COLUMN()-COLUMN($U$1)+1),""))} | Y26: {=IF($T26="","",_xlfn.XLOOKUP(TRIM($T26),ISE!$L:$L,INDEX(ISE!$N:$T,0,COLUMN()-COLUMN($U$1)+1),""))} | Z26: {=IF($T26="","",_xlfn.XLOOKUP(TRIM($T26),ISE!$L:$L,INDEX(ISE!$N:$T,0,COLUMN()-COLUMN($U$1)+1),""))} | AA26: {=IF($T26="","",_xlfn.XLOOKUP(TRIM($T26),ISE!$L:$L,INDEX(ISE!$N:$T,0,COLUMN()-COLUMN($U$1)+1),""))}
C27: Mon | D27: Tue | E27: Wed | F27: Thu | G27: Fri | H27: Sat | I27: Sun | K27: Block | L27: Mon | M27: Tue | N27: Wed | O27: Thu | P27: Fri | Q27: Sat | R27: Sun | U27: {=IF($T27="","",_xlfn.XLOOKUP(TRIM($T27),ISE!$L:$L,INDEX(ISE!$N:$T,0,COLUMN()-COLUMN($U$1)+1),""))} | V27: {=IF($T27="","",_xlfn.XLOOKUP(TRIM($T27),ISE!$L:$L,INDEX(ISE!$N:$T,0,COLUMN()-COLUMN($U$1)+1),""))} | W27: {=IF($T27="","",_xlfn.XLOOKUP(TRIM($T27),ISE!$L:$L,INDEX(ISE!$N:$T,0,COLUMN()-COLUMN($U$1)+1),""))} | X27: {=IF($T27="","",_xlfn.XLOOKUP(TRIM($T27),ISE!$L:$L,INDEX(ISE!$N:$T,0,COLUMN()-COLUMN($U$1)+1),""))} | Y27: {=IF($T27="","",_xlfn.XLOOKUP(TRIM($T27),ISE!$L:$L,INDEX(ISE!$N:$T,0,COLUMN()-COLUMN($U$1)+1),""))} | Z27: {=IF($T27="","",_xlfn.XLOOKUP(TRIM($T27),ISE!$L:$L,INDEX(ISE!$N:$T,0,COLUMN()-COLUMN($U$1)+1),""))} | AA27: {=IF($T27="","",_xlfn.XLOOKUP(TRIM($T27),ISE!$L:$L,INDEX(ISE!$N:$T,0,COLUMN()-COLUMN($U$1)+1),""))}
B28: 8:45am | C28: =SUM(C8:C11) -> 1339.832 | D28: =SUM(D8:D9) -> 455.16 | E28: =SUM(E8:E9) -> 500.426 | F28: =SUM(F8:F9) -> 408.354 | G28: =SUM(G8:G9) -> 393.586 | H28: =SUM(H8:H9) -> 532.568 | I28: =SUM(I8:I9) -> 620.43 | J28: //Morning | K28: =B28 -> 8:45am | L28: =IFERROR(C28/C$35,0) -> 0.16922105 | M28: =IFERROR(D28/D$35,0) -> 0.088678162 | N28: =IFERROR(E28/E$35,0) -> 0.08583816 | O28: =IFERROR(F28/F$35,0) -> 0.067631524 | P28: =IFERROR(G28/G$35,0) -> 0.049196344 | Q28: =IFERROR(H28/H$35,0) -> 0.066511589 | R28: =IFERROR(I28/I$35,0) -> 0.088529303 | U28: {=IF($T28="","",_xlfn.XLOOKUP(TRIM($T28),ISE!$L:$L,INDEX(ISE!$N:$T,0,COLUMN()-COLUMN($U$1)+1),""))} | V28: {=IF($T28="","",_xlfn.XLOOKUP(TRIM($T28),ISE!$L:$L,INDEX(ISE!$N:$T,0,COLUMN()-COLUMN($U$1)+1),""))} | W28: {=IF($T28="","",_xlfn.XLOOKUP(TRIM($T28),ISE!$L:$L,INDEX(ISE!$N:$T,0,COLUMN()-COLUMN($U$1)+1),""))} | X28: {=IF($T28="","",_xlfn.XLOOKUP(TRIM($T28),ISE!$L:$L,INDEX(ISE!$N:$T,0,COLUMN()-COLUMN($U$1)+1),""))} | Y28: {=IF($T28="","",_xlfn.XLOOKUP(TRIM($T28),ISE!$L:$L,INDEX(ISE!$N:$T,0,COLUMN()-COLUMN($U$1)+1),""))} | Z28: {=IF($T28="","",_xlfn.XLOOKUP(TRIM($T28),ISE!$L:$L,INDEX(ISE!$N:$T,0,COLUMN()-COLUMN($U$1)+1),""))} | AA28: {=IF($T28="","",_xlfn.XLOOKUP(TRIM($T28),ISE!$L:$L,INDEX(ISE!$N:$T,0,COLUMN()-COLUMN($U$1)+1),""))}
B29: 10:30am | C29: {=SUM(C10:C12+C14)} -> 2183.212 | D29: =SUM(D10:D12) -> 1293.71 | E29: =SUM(E10:E12) -> 1400.93 | F29: =SUM(F10:F12) -> 1348.56 | G29: =SUM(G10:G12) -> 1542.342 | H29: =SUM(H10:H12) -> 1926.422 | I29: =SUM(I10:I12) -> 2025.206 | J29: //Lunch | K29: =B29 -> 10:30am | L29: =IFERROR(C29/C$35,0) -> 0.27574011 | M29: =IFERROR(D29/D$35,0) -> 0.25205164 | N29: =IFERROR(E29/E$35,0) -> 0.24030177 | O29: =IFERROR(F29/F$35,0) -> 0.22334829 | P29: =IFERROR(G29/G$35,0) -> 0.19278528 | Q29: =IFERROR(H29/H$35,0) -> 0.24058784 | R29: =IFERROR(I29/I$35,0) -> 0.28897712 | U29: {=IF($T29="","",_xlfn.XLOOKUP(TRIM($T29),ISE!$L:$L,INDEX(ISE!$N:$T,0,COLUMN()-COLUMN($U$1)+1),""))} | V29: {=IF($T29="","",_xlfn.XLOOKUP(TRIM($T29),ISE!$L:$L,INDEX(ISE!$N:$T,0,COLUMN()-COLUMN($U$1)+1),""))} | W29: {=IF($T29="","",_xlfn.XLOOKUP(TRIM($T29),ISE!$L:$L,INDEX(ISE!$N:$T,0,COLUMN()-COLUMN($U$1)+1),""))} | X29: {=IF($T29="","",_xlfn.XLOOKUP(TRIM($T29),ISE!$L:$L,INDEX(ISE!$N:$T,0,COLUMN()-COLUMN($U$1)+1),""))} | Y29: {=IF($T29="","",_xlfn.XLOOKUP(TRIM($T29),ISE!$L:$L,INDEX(ISE!$N:$T,0,COLUMN()-COLUMN($U$1)+1),""))} | Z29: {=IF($T29="","",_xlfn.XLOOKUP(TRIM($T29),ISE!$L:$L,INDEX(ISE!$N:$T,0,COLUMN()-COLUMN($U$1)+1),""))} | AA29: {=IF($T29="","",_xlfn.XLOOKUP(TRIM($T29),ISE!$L:$L,INDEX(ISE!$N:$T,0,COLUMN()-COLUMN($U$1)+1),""))}
B30: 2:00pm | C30: =SUM(C14:C17) -> 1787.106 | D30: =SUM(D14:D16) -> 1042.736 | E30: =SUM(E14:E16) -> 1217.512 | F30: =SUM(F14:F16) -> 1290.028 | G30: =SUM(G14:G16) -> 1567.01 | H30: =SUM(H14:H16) -> 1856.148 | I30: =SUM(I14:I16) -> 1659.062 | J30: //Afternoon | K30: =B30 -> 2:00pm | L30: =IFERROR(C30/C$35,0) -> 0.22571184 | M30: =IFERROR(D30/D$35,0) -> 0.20315474 | N30: =IFERROR(E30/E$35,0) -> 0.20884005 | O30: =IFERROR(F30/F$35,0) -> 0.21365423 | P30: =IFERROR(G30/G$35,0) -> 0.19586866 | Q30: =IFERROR(H30/H$35,0) -> 0.23181143 | R30: =IFERROR(I30/I$35,0) -> 0.23673195 | U30: {=IF($T30="","",_xlfn.XLOOKUP(TRIM($T30),ISE!$L:$L,INDEX(ISE!$N:$T,0,COLUMN()-COLUMN($U$1)+1),""))} | V30: {=IF($T30="","",_xlfn.XLOOKUP(TRIM($T30),ISE!$L:$L,INDEX(ISE!$N:$T,0,COLUMN()-COLUMN($U$1)+1),""))} | W30: {=IF($T30="","",_xlfn.XLOOKUP(TRIM($T30),ISE!$L:$L,INDEX(ISE!$N:$T,0,COLUMN()-COLUMN($U$1)+1),""))} | X30: {=IF($T30="","",_xlfn.XLOOKUP(TRIM($T30),ISE!$L:$L,INDEX(ISE!$N:$T,0,COLUMN()-COLUMN($U$1)+1),""))} | Y30: {=IF($T30="","",_xlfn.XLOOKUP(TRIM($T30),ISE!$L:$L,INDEX(ISE!$N:$T,0,COLUMN()-COLUMN($U$1)+1),""))} | Z30: {=IF($T30="","",_xlfn.XLOOKUP(TRIM($T30),ISE!$L:$L,INDEX(ISE!$N:$T,0,COLUMN()-COLUMN($U$1)+1),""))} | AA30: {=IF($T30="","",_xlfn.XLOOKUP(TRIM($T30),ISE!$L:$L,INDEX(ISE!$N:$T,0,COLUMN()-COLUMN($U$1)+1),""))}
B31: 3:30pm | C31: =SUM(C16:C19) -> 2093.806 | D31: =SUM(D16:D18) -> 1621.852 | E31: =SUM(E16:E18) -> 2081.042 | F31: =SUM(F16:F18) -> 2198.276 | G31: =SUM(G16:G18) -> 3553.27 | H31: =SUM(H16:H18) -> 2898.11 | I31: =SUM(I16:I18) -> 2193.596 | J31: //Dinner | K31: =B31 -> 3:30pm | L31: =IFERROR(C31/C$35,0) -> 0.26444811 | M31: =IFERROR(D31/D$35,0) -> 0.31598307 | N31: =IFERROR(E31/E$35,0) -> 0.3569615 | O31: =IFERROR(F31/F$35,0) -> 0.36407812 | P31: =IFERROR(G31/G$35,0) -> 0.44414154 | Q31: =IFERROR(H31/H$35,0) -> 0.36194045 | R31: =IFERROR(I31/I$35,0) -> 0.31300473 | U31: {=IF($T31="","",_xlfn.XLOOKUP(TRIM($T31),ISE!$L:$L,INDEX(ISE!$N:$T,0,COLUMN()-COLUMN($U$1)+1),""))} | V31: {=IF($T31="","",_xlfn.XLOOKUP(TRIM($T31),ISE!$L:$L,INDEX(ISE!$N:$T,0,COLUMN()-COLUMN($U$1)+1),""))} | W31: {=IF($T31="","",_xlfn.XLOOKUP(TRIM($T31),ISE!$L:$L,INDEX(ISE!$N:$T,0,COLUMN()-COLUMN($U$1)+1),""))} | X31: {=IF($T31="","",_xlfn.XLOOKUP(TRIM($T31),ISE!$L:$L,INDEX(ISE!$N:$T,0,COLUMN()-COLUMN($U$1)+1),""))} | Y31: {=IF($T31="","",_xlfn.XLOOKUP(TRIM($T31),ISE!$L:$L,INDEX(ISE!$N:$T,0,COLUMN()-COLUMN($U$1)+1),""))} | Z31: {=IF($T31="","",_xlfn.XLOOKUP(TRIM($T31),ISE!$L:$L,INDEX(ISE!$N:$T,0,COLUMN()-COLUMN($U$1)+1),""))} | AA31: {=IF($T31="","",_xlfn.XLOOKUP(TRIM($T31),ISE!$L:$L,INDEX(ISE!$N:$T,0,COLUMN()-COLUMN($U$1)+1),""))}
B32: 7:00pm | C32: =SUM(C19:C22) -> 513.688 | D32: =SUM(D19:D21) -> 719.26 | E32: =SUM(E19:E21) -> 629.968 | F32: =SUM(F19:F21) -> 792.706 | G32: =SUM(G19:G21) -> 944.102 | H32: =SUM(H19:H21) -> 793.898 | I32: =SUM(I19:I21) -> 509.894 | J32: //After Dinner | K32: =B32 -> 7:00pm | L32: =IFERROR(C32/C$35,0) -> 0.064878896 | M32: =IFERROR(D32/D$35,0) -> 0.14013238 | N32: =IFERROR(E32/E$35,0) -> 0.10805852 | O32: =IFERROR(F32/F$35,0) -> 0.13128784 | P32: =IFERROR(G32/G$35,0) -> 0.11800818 | Q32: =IFERROR(H32/H$35,0) -> 0.099148685 | R32: =IFERROR(I32/I$35,0) -> 0.072756895 | U32: {=IF($T32="","",_xlfn.XLOOKUP(TRIM($T32),ISE!$L:$L,INDEX(ISE!$N:$T,0,COLUMN()-COLUMN($U$1)+1),""))} | V32: {=IF($T32="","",_xlfn.XLOOKUP(TRIM($T32),ISE!$L:$L,INDEX(ISE!$N:$T,0,COLUMN()-COLUMN($U$1)+1),""))} | W32: {=IF($T32="","",_xlfn.XLOOKUP(TRIM($T32),ISE!$L:$L,INDEX(ISE!$N:$T,0,COLUMN()-COLUMN($U$1)+1),""))} | X32: {=IF($T32="","",_xlfn.XLOOKUP(TRIM($T32),ISE!$L:$L,INDEX(ISE!$N:$T,0,COLUMN()-COLUMN($U$1)+1),""))} | Y32: {=IF($T32="","",_xlfn.XLOOKUP(TRIM($T32),ISE!$L:$L,INDEX(ISE!$N:$T,0,COLUMN()-COLUMN($U$1)+1),""))} | Z32: {=IF($T32="","",_xlfn.XLOOKUP(TRIM($T32),ISE!$L:$L,INDEX(ISE!$N:$T,0,COLUMN()-COLUMN($U$1)+1),""))} | AA32: {=IF($T32="","",_xlfn.XLOOKUP(TRIM($T32),ISE!$L:$L,INDEX(ISE!$N:$T,0,COLUMN()-COLUMN($U$1)+1),""))}
B33: Late Night | U33: {=IF($T33="","",_xlfn.XLOOKUP(TRIM($T33),ISE!$L:$L,INDEX(ISE!$N:$T,0,COLUMN()-COLUMN($U$1)+1),""))} | V33: {=IF($T33="","",_xlfn.XLOOKUP(TRIM($T33),ISE!$L:$L,INDEX(ISE!$N:$T,0,COLUMN()-COLUMN($U$1)+1),""))} | W33: {=IF($T33="","",_xlfn.XLOOKUP(TRIM($T33),ISE!$L:$L,INDEX(ISE!$N:$T,0,COLUMN()-COLUMN($U$1)+1),""))} | X33: {=IF($T33="","",_xlfn.XLOOKUP(TRIM($T33),ISE!$L:$L,INDEX(ISE!$N:$T,0,COLUMN()-COLUMN($U$1)+1),""))} | Y33: {=IF($T33="","",_xlfn.XLOOKUP(TRIM($T33),ISE!$L:$L,INDEX(ISE!$N:$T,0,COLUMN()-COLUMN($U$1)+1),""))} | Z33: {=IF($T33="","",_xlfn.XLOOKUP(TRIM($T33),ISE!$L:$L,INDEX(ISE!$N:$T,0,COLUMN()-COLUMN($U$1)+1),""))} | AA33: {=IF($T33="","",_xlfn.XLOOKUP(TRIM($T33),ISE!$L:$L,INDEX(ISE!$N:$T,0,COLUMN()-COLUMN($U$1)+1),""))}
U34: {=IF($T34="","",_xlfn.XLOOKUP(TRIM($T34),ISE!$L:$L,INDEX(ISE!$N:$T,0,COLUMN()-COLUMN($U$1)+1),""))} | V34: {=IF($T34="","",_xlfn.XLOOKUP(TRIM($T34),ISE!$L:$L,INDEX(ISE!$N:$T,0,COLUMN()-COLUMN($U$1)+1),""))} | W34: {=IF($T34="","",_xlfn.XLOOKUP(TRIM($T34),ISE!$L:$L,INDEX(ISE!$N:$T,0,COLUMN()-COLUMN($U$1)+1),""))} | X34: {=IF($T34="","",_xlfn.XLOOKUP(TRIM($T34),ISE!$L:$L,INDEX(ISE!$N:$T,0,COLUMN()-COLUMN($U$1)+1),""))} | Y34: {=IF($T34="","",_xlfn.XLOOKUP(TRIM($T34),ISE!$L:$L,INDEX(ISE!$N:$T,0,COLUMN()-COLUMN($U$1)+1),""))} | Z34: {=IF($T34="","",_xlfn.XLOOKUP(TRIM($T34),ISE!$L:$L,INDEX(ISE!$N:$T,0,COLUMN()-COLUMN($U$1)+1),""))} | AA34: {=IF($T34="","",_xlfn.XLOOKUP(TRIM($T34),ISE!$L:$L,INDEX(ISE!$N:$T,0,COLUMN()-COLUMN($U$1)+1),""))}
B35: Totals | C35: =SUM(C28:C33) -> 7917.644 | D35: =SUM(D28:D33) -> 5132.718 | E35: =SUM(E28:E33) -> 5829.878 | F35: =SUM(F28:F33) -> 6037.924 | G35: =SUM(G28:G33) -> 8000.31 | H35: =SUM(H28:H33) -> 8007.146 | I35: =SUM(I28:I33) -> 7008.188 | K35: =B35 -> Totals | L35: =IFERROR(C35/C$35,0) -> 1 | M35: =IFERROR(D35/D$35,0) -> 1 | N35: =IFERROR(E35/E$35,0) -> 1 | O35: =IFERROR(F35/F$35,0) -> 1 | P35: =IFERROR(G35/G$35,0) -> 1 | Q35: =IFERROR(H35/H$35,0) -> 1 | R35: =IFERROR(I35/I$35,0) -> 1 | U35: {=IF($T35="","",_xlfn.XLOOKUP(TRIM($T35),ISE!$L:$L,INDEX(ISE!$N:$T,0,COLUMN()-COLUMN($U$1)+1),""))} | V35: {=IF($T35="","",_xlfn.XLOOKUP(TRIM($T35),ISE!$L:$L,INDEX(ISE!$N:$T,0,COLUMN()-COLUMN($U$1)+1),""))} | W35: {=IF($T35="","",_xlfn.XLOOKUP(TRIM($T35),ISE!$L:$L,INDEX(ISE!$N:$T,0,COLUMN()-COLUMN($U$1)+1),""))} | X35: {=IF($T35="","",_xlfn.XLOOKUP(TRIM($T35),ISE!$L:$L,INDEX(ISE!$N:$T,0,COLUMN()-COLUMN($U$1)+1),""))} | Y35: {=IF($T35="","",_xlfn.XLOOKUP(TRIM($T35),ISE!$L:$L,INDEX(ISE!$N:$T,0,COLUMN()-COLUMN($U$1)+1),""))} | Z35: {=IF($T35="","",_xlfn.XLOOKUP(TRIM($T35),ISE!$L:$L,INDEX(ISE!$N:$T,0,COLUMN()-COLUMN($U$1)+1),""))} | AA35: {=IF($T35="","",_xlfn.XLOOKUP(TRIM($T35),ISE!$L:$L,INDEX(ISE!$N:$T,0,COLUMN()-COLUMN($U$1)+1),""))}
C36: =IF(C35=C24, 1, 0) -> 0 | D36: =IF(D35=D24, 1, 0) -> 0 | E36: =IF(E35=E24, 1, 0) -> 0 | F36: =IF(F35=F24, 1, 0) -> 0 | G36: =IF(G35=G24, 1, 0) -> 0 | H36: =IF(H35=H24, 1, 0) -> 0 | I36: =IF(I35=I24, 1, 0) -> 0 | U36: {=IF($T36="","",_xlfn.XLOOKUP(TRIM($T36),ISE!$L:$L,INDEX(ISE!$N:$T,0,COLUMN()-COLUMN($U$1)+1),""))} | V36: {=IF($T36="","",_xlfn.XLOOKUP(TRIM($T36),ISE!$L:$L,INDEX(ISE!$N:$T,0,COLUMN()-COLUMN($U$1)+1),""))} | W36: {=IF($T36="","",_xlfn.XLOOKUP(TRIM($T36),ISE!$L:$L,INDEX(ISE!$N:$T,0,COLUMN()-COLUMN($U$1)+1),""))} | X36: {=IF($T36="","",_xlfn.XLOOKUP(TRIM($T36),ISE!$L:$L,INDEX(ISE!$N:$T,0,COLUMN()-COLUMN($U$1)+1),""))} | Y36: {=IF($T36="","",_xlfn.XLOOKUP(TRIM($T36),ISE!$L:$L,INDEX(ISE!$N:$T,0,COLUMN()-COLUMN($U$1)+1),""))} | Z36: {=IF($T36="","",_xlfn.XLOOKUP(TRIM($T36),ISE!$L:$L,INDEX(ISE!$N:$T,0,COLUMN()-COLUMN($U$1)+1),""))} | AA36: {=IF($T36="","",_xlfn.XLOOKUP(TRIM($T36),ISE!$L:$L,INDEX(ISE!$N:$T,0,COLUMN()-COLUMN($U$1)+1),""))}
U37: {=IF($T37="","",_xlfn.XLOOKUP(TRIM($T37),ISE!$L:$L,INDEX(ISE!$N:$T,0,COLUMN()-COLUMN($U$1)+1),""))} | V37: {=IF($T37="","",_xlfn.XLOOKUP(TRIM($T37),ISE!$L:$L,INDEX(ISE!$N:$T,0,COLUMN()-COLUMN($U$1)+1),""))} | W37: {=IF($T37="","",_xlfn.XLOOKUP(TRIM($T37),ISE!$L:$L,INDEX(ISE!$N:$T,0,COLUMN()-COLUMN($U$1)+1),""))} | X37: {=IF($T37="","",_xlfn.XLOOKUP(TRIM($T37),ISE!$L:$L,INDEX(ISE!$N:$T,0,COLUMN()-COLUMN($U$1)+1),""))} | Y37: {=IF($T37="","",_xlfn.XLOOKUP(TRIM($T37),ISE!$L:$L,INDEX(ISE!$N:$T,0,COLUMN()-COLUMN($U$1)+1),""))} | Z37: {=IF($T37="","",_xlfn.XLOOKUP(TRIM($T37),ISE!$L:$L,INDEX(ISE!$N:$T,0,COLUMN()-COLUMN($U$1)+1),""))} | AA37: {=IF($T37="","",_xlfn.XLOOKUP(TRIM($T37),ISE!$L:$L,INDEX(ISE!$N:$T,0,COLUMN()-COLUMN($U$1)+1),""))}
U38: {=IF($T38="","",_xlfn.XLOOKUP(TRIM($T38),ISE!$L:$L,INDEX(ISE!$N:$T,0,COLUMN()-COLUMN($U$1)+1),""))} | V38: {=IF($T38="","",_xlfn.XLOOKUP(TRIM($T38),ISE!$L:$L,INDEX(ISE!$N:$T,0,COLUMN()-COLUMN($U$1)+1),""))} | W38: {=IF($T38="","",_xlfn.XLOOKUP(TRIM($T38),ISE!$L:$L,INDEX(ISE!$N:$T,0,COLUMN()-COLUMN($U$1)+1),""))} | X38: {=IF($T38="","",_xlfn.XLOOKUP(TRIM($T38),ISE!$L:$L,INDEX(ISE!$N:$T,0,COLUMN()-COLUMN($U$1)+1),""))} | Y38: {=IF($T38="","",_xlfn.XLOOKUP(TRIM($T38),ISE!$L:$L,INDEX(ISE!$N:$T,0,COLUMN()-COLUMN($U$1)+1),""))} | Z38: {=IF($T38="","",_xlfn.XLOOKUP(TRIM($T38),ISE!$L:$L,INDEX(ISE!$N:$T,0,COLUMN()-COLUMN($U$1)+1),""))} | AA38: {=IF($T38="","",_xlfn.XLOOKUP(TRIM($T38),ISE!$L:$L,INDEX(ISE!$N:$T,0,COLUMN()-COLUMN($U$1)+1),""))}
K39: =SUM(IFERROR(Sales!BT$17*Sales!BK30/SUM(Sales!BK$28:BK$32),0)*$L$3) | U39: {=IF($T39="","",_xlfn.XLOOKUP(TRIM($T39),ISE!$L:$L,INDEX(ISE!$N:$T,0,COLUMN()-COLUMN($U$1)+1),""))} | V39: {=IF($T39="","",_xlfn.XLOOKUP(TRIM($T39),ISE!$L:$L,INDEX(ISE!$N:$T,0,COLUMN()-COLUMN($U$1)+1),""))} | W39: {=IF($T39="","",_xlfn.XLOOKUP(TRIM($T39),ISE!$L:$L,INDEX(ISE!$N:$T,0,COLUMN()-COLUMN($U$1)+1),""))} | X39: {=IF($T39="","",_xlfn.XLOOKUP(TRIM($T39),ISE!$L:$L,INDEX(ISE!$N:$T,0,COLUMN()-COLUMN($U$1)+1),""))} | Y39: {=IF($T39="","",_xlfn.XLOOKUP(TRIM($T39),ISE!$L:$L,INDEX(ISE!$N:$T,0,COLUMN()-COLUMN($U$1)+1),""))} | Z39: {=IF($T39="","",_xlfn.XLOOKUP(TRIM($T39),ISE!$L:$L,INDEX(ISE!$N:$T,0,COLUMN()-COLUMN($U$1)+1),""))} | AA39: {=IF($T39="","",_xlfn.XLOOKUP(TRIM($T39),ISE!$L:$L,INDEX(ISE!$N:$T,0,COLUMN()-COLUMN($U$1)+1),""))}
U40: {=IF($T40="","",_xlfn.XLOOKUP(TRIM($T40),ISE!$L:$L,INDEX(ISE!$N:$T,0,COLUMN()-COLUMN($U$1)+1),""))} | V40: {=IF($T40="","",_xlfn.XLOOKUP(TRIM($T40),ISE!$L:$L,INDEX(ISE!$N:$T,0,COLUMN()-COLUMN($U$1)+1),""))} | W40: {=IF($T40="","",_xlfn.XLOOKUP(TRIM($T40),ISE!$L:$L,INDEX(ISE!$N:$T,0,COLUMN()-COLUMN($U$1)+1),""))} | X40: {=IF($T40="","",_xlfn.XLOOKUP(TRIM($T40),ISE!$L:$L,INDEX(ISE!$N:$T,0,COLUMN()-COLUMN($U$1)+1),""))} | Y40: {=IF($T40="","",_xlfn.XLOOKUP(TRIM($T40),ISE!$L:$L,INDEX(ISE!$N:$T,0,COLUMN()-COLUMN($U$1)+1),""))} | Z40: {=IF($T40="","",_xlfn.XLOOKUP(TRIM($T40),ISE!$L:$L,INDEX(ISE!$N:$T,0,COLUMN()-COLUMN($U$1)+1),""))} | AA40: {=IF($T40="","",_xlfn.XLOOKUP(TRIM($T40),ISE!$L:$L,INDEX(ISE!$N:$T,0,COLUMN()-COLUMN($U$1)+1),""))}
U41: {=IF($T41="","",_xlfn.XLOOKUP(TRIM($T41),ISE!$L:$L,INDEX(ISE!$N:$T,0,COLUMN()-COLUMN($U$1)+1),""))} | V41: {=IF($T41="","",_xlfn.XLOOKUP(TRIM($T41),ISE!$L:$L,INDEX(ISE!$N:$T,0,COLUMN()-COLUMN($U$1)+1),""))} | W41: {=IF($T41="","",_xlfn.XLOOKUP(TRIM($T41),ISE!$L:$L,INDEX(ISE!$N:$T,0,COLUMN()-COLUMN($U$1)+1),""))} | X41: {=IF($T41="","",_xlfn.XLOOKUP(TRIM($T41),ISE!$L:$L,INDEX(ISE!$N:$T,0,COLUMN()-COLUMN($U$1)+1),""))} | Y41: {=IF($T41="","",_xlfn.XLOOKUP(TRIM($T41),ISE!$L:$L,INDEX(ISE!$N:$T,0,COLUMN()-COLUMN($U$1)+1),""))} | Z41: {=IF($T41="","",_xlfn.XLOOKUP(TRIM($T41),ISE!$L:$L,INDEX(ISE!$N:$T,0,COLUMN()-COLUMN($U$1)+1),""))} | AA41: {=IF($T41="","",_xlfn.XLOOKUP(TRIM($T41),ISE!$L:$L,INDEX(ISE!$N:$T,0,COLUMN()-COLUMN($U$1)+1),""))}
U42: {=IF($T42="","",_xlfn.XLOOKUP(TRIM($T42),ISE!$L:$L,INDEX(ISE!$N:$T,0,COLUMN()-COLUMN($U$1)+1),""))} | V42: {=IF($T42="","",_xlfn.XLOOKUP(TRIM($T42),ISE!$L:$L,INDEX(ISE!$N:$T,0,COLUMN()-COLUMN($U$1)+1),""))} | W42: {=IF($T42="","",_xlfn.XLOOKUP(TRIM($T42),ISE!$L:$L,INDEX(ISE!$N:$T,0,COLUMN()-COLUMN($U$1)+1),""))} | X42: {=IF($T42="","",_xlfn.XLOOKUP(TRIM($T42),ISE!$L:$L,INDEX(ISE!$N:$T,0,COLUMN()-COLUMN($U$1)+1),""))} | Y42: {=IF($T42="","",_xlfn.XLOOKUP(TRIM($T42),ISE!$L:$L,INDEX(ISE!$N:$T,0,COLUMN()-COLUMN($U$1)+1),""))} | Z42: {=IF($T42="","",_xlfn.XLOOKUP(TRIM($T42),ISE!$L:$L,INDEX(ISE!$N:$T,0,COLUMN()-COLUMN($U$1)+1),""))} | AA42: {=IF($T42="","",_xlfn.XLOOKUP(TRIM($T42),ISE!$L:$L,INDEX(ISE!$N:$T,0,COLUMN()-COLUMN($U$1)+1),""))}
U43: {=IF($T43="","",_xlfn.XLOOKUP(TRIM($T43),ISE!$L:$L,INDEX(ISE!$N:$T,0,COLUMN()-COLUMN($U$1)+1),""))} | V43: {=IF($T43="","",_xlfn.XLOOKUP(TRIM($T43),ISE!$L:$L,INDEX(ISE!$N:$T,0,COLUMN()-COLUMN($U$1)+1),""))} | W43: {=IF($T43="","",_xlfn.XLOOKUP(TRIM($T43),ISE!$L:$L,INDEX(ISE!$N:$T,0,COLUMN()-COLUMN($U$1)+1),""))} | X43: {=IF($T43="","",_xlfn.XLOOKUP(TRIM($T43),ISE!$L:$L,INDEX(ISE!$N:$T,0,COLUMN()-COLUMN($U$1)+1),""))} | Y43: {=IF($T43="","",_xlfn.XLOOKUP(TRIM($T43),ISE!$L:$L,INDEX(ISE!$N:$T,0,COLUMN()-COLUMN($U$1)+1),""))} | Z43: {=IF($T43="","",_xlfn.XLOOKUP(TRIM($T43),ISE!$L:$L,INDEX(ISE!$N:$T,0,COLUMN()-COLUMN($U$1)+1),""))} | AA43: {=IF($T43="","",_xlfn.XLOOKUP(TRIM($T43),ISE!$L:$L,INDEX(ISE!$N:$T,0,COLUMN()-COLUMN($U$1)+1),""))}
U44: {=IF($T44="","",_xlfn.XLOOKUP(TRIM($T44),ISE!$L:$L,INDEX(ISE!$N:$T,0,COLUMN()-COLUMN($U$1)+1),""))} | V44: {=IF($T44="","",_xlfn.XLOOKUP(TRIM($T44),ISE!$L:$L,INDEX(ISE!$N:$T,0,COLUMN()-COLUMN($U$1)+1),""))} | W44: {=IF($T44="","",_xlfn.XLOOKUP(TRIM($T44),ISE!$L:$L,INDEX(ISE!$N:$T,0,COLUMN()-COLUMN($U$1)+1),""))} | X44: {=IF($T44="","",_xlfn.XLOOKUP(TRIM($T44),ISE!$L:$L,INDEX(ISE!$N:$T,0,COLUMN()-COLUMN($U$1)+1),""))} | Y44: {=IF($T44="","",_xlfn.XLOOKUP(TRIM($T44),ISE!$L:$L,INDEX(ISE!$N:$T,0,COLUMN()-COLUMN($U$1)+1),""))} | Z44: {=IF($T44="","",_xlfn.XLOOKUP(TRIM($T44),ISE!$L:$L,INDEX(ISE!$N:$T,0,COLUMN()-COLUMN($U$1)+1),""))} | AA44: {=IF($T44="","",_xlfn.XLOOKUP(TRIM($T44),ISE!$L:$L,INDEX(ISE!$N:$T,0,COLUMN()-COLUMN($U$1)+1),""))}
...

Sheet Sales
